Workbook

Sheet README
A1: IntelCost Equipment Catalog - review draft
A2: Built 2026-10-21 from the research notes in 'Construction equipment catalog and rates' (no new research). For review by the Director of Estimating, then for building the Equipment List library and the equipment picker in the Equipment cost component.
A4: How a row is used in the app
A5: 1. Pick | B5: User picks Equipment type -> size class (one Equipment row, Equip_ID).
A6: 2. Activity | B6: User picks an Activity the machine serves (Equipment.Activities lists the Activity_IDs; Production holds the Equip_ID x Activity_ID rates). Production auto-fills Prod_typical (low/high shown for judgement).
A7: 3. Hours | B7: Hours = Quantity / Production (convert BCY/LCY/CCY with Factors section 1). For crew/DOT daily rates: days = Quantity / daily rate; equipment hours = days x shift hours. Duration-based equipment (lifts, cranes, telehandlers, compressors, generators, lights, pumps, shoring, site) has no production rate: duration = the served crew/activity duration (Duration_Norms).
A8: 4. Cost | B8: Cost = equipment basis + fuel + operator + mob/demob: - Rental basis: Rent_day/week/4wk (bare, no operator, no fuel), chosen by duration (cheapest combination), x equipment location factor (Settings B8). - Owned basis: Owned_rate_hr_excl_fuel x hours x location factor. - Fuel: Fuel_gal_hr_med (low/high by duty) x hours x user fuel price (Settings B4). Do NOT add fuel to Owned_rate_hr_incl_fuel. - Operator: hours x the project's wage set for Typical_operator_craft (labor). NEVER from this workbook. - Operated rows (Rent_basis = operated: cranes, concrete pumps, dump trucks with driver) already include the operator; do not add labor. - Mob + demob: one-time per move, counted once per resource per project (Mob_Demob; Default_mob_one_way / Default_demob_one_way at Settings B6 miles).
A10: Sheets
A11: README | B11: This page: workflow, column dictionary, confidence legend, rate dates, caveats.
A12: Equipment | B12: One row per equipment size class (628 rows). Rates, fuel, transport, default mob/demob, activities, notes and flags.
A13: Activities | B13: Activity master: unit, norm basis (per hour at 50-min hour vs per 8-hr / working day), method formula, inputs, sources, type (Production / Duration / Quantity).
A14: Production | B14: Equip_ID x Activity_ID (592 rows): Prod_low / typical / high with unit, basis, default conditions, calculation shown, sources, confidence. Calculated rows are live formulas driven by Input_capacity (yellow) and Settings (efficiency, speeds).
A15: Duration_Norms | B15: How duration is derived for duration-based equipment; minimum hours/rental periods; shift/overtime; standby; Caltrans delay/OT factors.
A16: Factors | B16: Soil conversions, fill factors, efficiency, operator, dozer corrections, rolling resistance, cycle components, compaction (16.3), water, grader, fuel factors.
A17: Mob_Demob | B17: Transport classes with $/loaded mile, minimums, permits, escorts; calculator; legal limits; rental delivery norms.
A18: Rental_Terms | B18: Hour limits (8/40/160 vs 176), overtime, multipliers observed, damage waiver, environmental fee, refuel, shift multipliers.
A19: Location | B19: Method (equipment factor / local fuel / wage-set operator) and evidence (RSMeans IL, Blue Book, EIA PADD diesel).
A20: Sources | B20: Source_ID register: title, publisher, edition/date, URL, what it supports.
A21: Gaps | B21: Every missing or weak item with impact and the recommended way to close it; live counts.
A22: Settings | B22: All assumptions referenced by formulas: fuel prices, FEMA back-out diesel price, default mob distance, job efficiency, location factor, fuel factors, multipliers, production speeds. Blue = editable.
A24: Confidence legend (Rent_confidence, Owned_confidence, Production.Confidence)
A25: A (green) | B25: Sourced from 2+ sources that are not derived from each other; median used (per-source values in Notes). ScaffoldExchange (cites Sunbelt/URI/BigRentz) does not count as independent of COSTARS or BigRentz; broad DOZR bands (60-120, 120-180 ft) are not counted as class sources.
A26: B (blue) | B26: Single source, or several sources that are not independent (value as published; FEMA rows are B).
A27: C (amber) | B27: Derived by a stated method: interpolation between adjacent sourced classes (never extrapolated), week/4-week from day by the Settings multipliers, fuel back-out, HP x 0.0486 x load factor, or production calculated from documented formulas. Method is written in Notes / Calc_shown.
A28: D (grey) | B28: No basis. Rate cell left blank; Flags says 'Needs rate' (or 'Needs fuel gal/hr' / input needed). Production rows become D whenever their driving input is blank.
A30: Column dictionary - Equipment
A31: Equip_ID | B31: Stable readable key (TYPE-SUBTYPE-SIZE). Never reuse a retired ID.
A32: Category / Type / Sub_type / Size_class | B32: Picker hierarchy.
A33: Defining_spec / Spec_value / Spec_unit | B33: The spec that defines the class (operating weight, net HP, bucket, ROC, drum width, platform height, capacity...).
A34: Example_models | B34: Representative models from the sources (not an endorsement).
A35: Operating_weight_lb / Net_HP | B35: Representative values from notes (blank = not in notes).
A36: Capacity / Platform_or_lift_height_ft | B36: Bucket/payload/lift capacity; platform height (lifts), lift height (telehandlers).
A37: Fuel_type | B37: diesel / gas / electric / dual / hybrid / propane / none.
A38: Typical_operator_craft | B38: Craft label only - wages come from the project wage set.
A39: Default_billing_basis | B39: day/wk/4wk (bare rental), hr (operated or owned), 4wk/month, LF etc.
A40: Rent_day / Rent_week / Rent_4wk | B40: Bare rental (no operator, no fuel), USD. 4-week = 28 days (Wheeler 176 hr, others 160 hr).
A41: Rent_low_4wk / Rent_high_4wk | B41: Lowest/highest 4-week value across the sources used. For a single source they are blank, EXCEPT where that one source publishes its own range (office trailers, containers, fence, tower crane, rentd compressors) - then they hold that range (see Notes).
A42: Rent_basis | B42: bare or operated.
... A55: Notes / Flags | B55: Every derivation is described in Notes; Flags list Needs rate / Needs fuel / FEMA ⚠ / label corrections.
A57: Rate dates
...

Sheet Equipment
A1: Equip_ID | B1: Category | C1: Type | D1: Sub_type | E1: Size_class | F1: Defining_spec | G1: Spec_value | H1: Spec_unit | I1: Example_models | J1: Operating_weight_lb | K1: Net_HP | L1: Capacity | M1: Platform_or_lift_height_ft | N1: Fuel_type | O1: Typical_operator_craft | P1: Default_billing_basis | Q1: Rent_day | R1: Rent_week | S1: Rent_4wk | T1: Rent_low_4wk | U1: Rent_high_4wk | V1: Rent_basis | W1: Rent_hr_operated | X1: Operated_min_hr | Y1: Rent_source_ids | Z1: Rent_date | AA1: Rent_confidence | AB1: FEMA_code | AC1: Owned_rate_hr_incl_fuel | AD1: Owned_rate_year | AE1: Fuel_gal_hr_low | AF1: Fuel_gal_hr_med | AG1: Fuel_gal_hr_high | AH1: Fuel_source | AI1: Owned_rate_hr_excl_fuel | AJ1: Owned_confidence | AK1: Owned_excl_fuel_confidence | AL1: Standby_rule | AM1: Transport_class | AN1: Transport_weight_lb | AO1: Transport_width_ft | AP1: Permit_likely | AQ1: Default_mob_one_way | AR1: Default_demob_one_way | AS1: Activities | AT1: Notes | AU1: Flags
A2: DZ-CRAWL-D1 | B2: Earthwork | C2: Crawler dozer | D2: Small (Cat D1-D3) | E2: D1 class (~80 hp) | F2: Net HP | G2: 80 | H2: hp | I2: Cat D1 (formerly D3K2) | J2: 17855 | K2: 80 | L2: Blade Cat D1 std blade 1.99 yd3 (LGP 2.17) | N2: diesel | O2: Operating Engineer - heavy equip. group (per WD) | P2: day/wk/4wk | V2: bare | AA2: D | AB2: 8250 | AC2: 47.73 | AD2: FEMA 2025 | AE2: =ROUND(K2*Settings!$B$11*Settings!$B$13,2) -> 1.36 | AF2: =ROUND(K2*Settings!$B$11*Settings!$B$14,2) -> 1.79 | AG2: =ROUND(K2*Settings!$B$11*Settings!$B$15,2) -> 2.33 | AH2: Derived (C): Net_HP x 0.0486 diesel gal/bhp-hr x load factor 0.35/0.46/0.60 [USACE-EP] | AI2: =IF(OR(AC2="",AF2="",Settings!$B$5=""),"",ROUND(AC2-AF2*Settings!$B$5,2)) -> 41.18 | AJ2: B | AK2: C | AL2: Owned: USACE standby = 0.5 x DEPR + FCCM, max 40 hr/wk [USACE-EP]; with only an all-in rate use Caltrans delay factor x rate, max 8 hr/day & 40 hr/wk [CALT-2627]: no class factor captured, use 0.10-0.22 band (inference). Rental: accrues by calendar period. FEMA: not eligible unless intermittent use [FEMA-PG]. | AM2: tilt-trailer | AN2: 17855 | AP2: N | AQ2: =IFERROR(IF(AND(INDEX(Mob_Demob!$D$6:$D$14,MATCH(AM2,Mob_Demob!$A$6:$A$14,0))="",INDEX(Mob_Demob!$G$6:$G$14,MATCH(AM2,Mob_Demob!$A$6:$A$14,0))=""),"",ROUND(MAX(N(INDEX(Mob_Demob!$G$6:$G$14,MATCH(AM2,Mob_Demob!$A$6:$A$14,0))),N(INDEX(Mob_Demob!$D$6:$D$14,MATCH(AM2,Mob_Demob!$A$6:$A$14,0)))*Settings!$B$6)+IF(AP2="Y",N(INDEX(Mob_Demob!$I$6:$I$14,MATCH(AM2,Mob_Demob!$A$6:$A$14,0)))*Settings!$B$19,0)+N(INDEX(Mob_Demob!$L$6:$L$14,MATCH(AM2,Mob_Demob!$A$6:$A$14,0)))*N(INDEX(Mob_Demob!$K$6:$K$14,MATCH(AM2,Mob_Demob!$A$6:$A$14,0)))*Settings!$B$6+N(INDEX(Mob_Demob!$M$6:$M$14,MATCH(AM2,Mob_Demob!$A$6:$A$14,0)))*N(INDEX(Mob_Demob!$N$6:$N$14,MATCH(AM2,Mob_Demob!$A$6:$A$14,0))),0)),"") -> 500 | AR2: =IF(AQ2="","",ROUND(AQ2*Settings!$B$18,0)) -> 500 | AS2: EW-STRIP,EW-PUSH-100,EW-SPREAD,EW-RGRADE | AT2: Weight/HP Ziegler. Max speeds F 5.6 / R 6.2 mph (hydrostatic) [CAT-DOZ-PG]; production uses Settings dozing speeds because no working-speed reduction is sourced. Fuel gal/hr derived (C): Net_HP x USACE fuel factor x load factor (Settings B11-B15). Ex-fuel (C) = FEMA incl-fuel rate - Fuel_gal_hr_med x diesel back-out price (Settings B5). | AU2: Needs rate (rental)
A3: DZ-CRAWL-D2 | B3: Earthwork | C3: Crawler dozer | D3: Small (Cat D1-D3) | E3: D2 class (85+ hp) | F3: Net HP (min) | G3: 85 | H3: hp | I3: Cat D2 (formerly D4K2; 92 hp, 18,382 lb) | J3: 18382 | K3: 92 | L3: Blade Cat D2 std 2.59 yd3 (LGP 2.42) | N3: diesel | O3: Operating Engineer - heavy equip. group (per WD) | P3: day/wk/4wk | V3: bare | AA3: D | AC3: =ROUND(AC2+(AC4-AC2)*(K3-K2)/(K4-K2),2) -> 55.96 | AD3: FEMA 2025 (interpolated) | AE3: =ROUND(K3*Settings!$B$11*Settings!$B$13,2) -> 1.56 | AF3: =ROUND(K3*Settings!$B$11*Settings!$B$14,2) -> 2.06 | AG3: =ROUND(K3*Settings!$B$11*Settings!$B$15,2) -> 2.68 | AH3: Derived (C): Net_HP x 0.0486 diesel gal/bhp-hr x load factor 0.35/0.46/0.60 [USACE-EP] | AI3: =IF(OR(AC3="",AF3="",Settings!$B$5=""),"",ROUND(AC3-AF3*Settings!$B$5,2)) -> 48.42 | AJ3: C | AK3: C | AL3: Owned: USACE standby = 0.5 x DEPR + FCCM, max 40 hr/wk [USACE-EP]; with only an all-in rate use Caltrans delay factor x rate, max 8 hr/day & 40 hr/wk [CALT-2627]: no class factor captured, use 0.10-0.22 band (inference). Rental: accrues by calendar period. FEMA: not eligible unless intermittent use [FEMA-PG]. | AM3: tilt-trailer | AN3: 18382 | AP3: N | AQ3: =IFERROR(IF(AND(INDEX(Mob_Demob!$D$6:$D$14,MATCH(AM3,Mob_Demob!$A$6:$A$14,0))="",INDEX(Mob_Demob!$G$6:$G$14,MATCH(AM3,Mob_Demob!$A$6:$A$14,0))=""),"",ROUND(MAX(N(INDEX(Mob_Demob!$G$6:$G$14,MATCH(AM3,Mob_Demob!$A$6:$A$14,0))),N(INDEX(Mob_Demob!$D$6:$D$14,MATCH(AM3,Mob_Demob!$A$6:$A$14,0)))*Settings!$B$6)+IF(AP3="Y",N(INDEX(Mob_Demob!$I$6:$I$14,MATCH(AM3,Mob_Demob!$A$6:$A$14,0)))*Settings!$B$19,0)+N(INDEX(Mob_Demob!$L$6:$L$14,MATCH(AM3,Mob_Demob!$A$6:$A$14,0)))*N(INDEX(Mob_Demob!$K$6:$K$14,MATCH(AM3,Mob_Demob!$A$6:$A$14,0)))*Settings!$B$6+N(INDEX(Mob_Demob!$M$6:$M$14,MATCH(AM3,Mob_Demob!$A$6:$A$14,0)))*N(INDEX(Mob_Demob!$N$6:$N$14,MATCH(AM3,Mob_Demob!$A$6:$A$14,0))),0)),"") -> 500 | AR3: =IF(AQ3="","",ROUND(AQ3*Settings!$B$18,0)) -> 500 | AS3: EW-STRIP,EW-PUSH-100,EW-SPREAD,EW-RGRADE | AT3: Only the Cat minimum HP (85+) is sourced (Carter); no weight, HP, fuel or rates. Specs from Western States Cat D2 page [CAT-DOZ-PG]. Owned_rate_hr_incl_fuel interpolated (C) between DZ-CRAWL-D1 and DZ-CRAWL-D3 by Net HP (FEMA 2025 endpoints). Fuel gal/hr derived (C): Net_HP x USACE fuel factor x load factor (Settings B11-B15). Ex-fuel (C) = FEMA incl-fuel rate - Fuel_gal_hr_med x diesel back-out price (Settings B5). | AU3: Needs rate (rental)
A4: DZ-CRAWL-D3 | B4: Earthwork | C4: Crawler dozer | D4: Small (Cat D1-D3) | E4: D3 class (~100-104 hp, 20-24k lb) | F4: Net HP | G4: 104 | H4: hp | I4: Cat D3; Komatsu D39EX/PX; Develon DD100/130 | J4: 20640 | K4: 104 | L4: Blade Cat D3 std 2.86 yd3 (LGP 3.06) | N4: diesel | O4: Operating Engineer - heavy equip. group (per WD) | P4: day/wk/4wk | Q4: 875 | R4: 2629 | S4: 6900 | T4: 5413 | U4: 7623 | V4: bare | Y4: W25;C25;R25 | Z4: 2025-2026 | AA4: A | AB4: 8251 | AC4: 64.18 | AD4: FEMA 2025 | AE4: 1.51 | AF4: 1.93 | AG4: 2.36 | AH4: Cat VisionLink Dec 2022, model D3-12 [CATFUEL22] | AI4: =IF(OR(AC4="",AF4="",Settings!$B$5=""),"",ROUND(AC4-AF4*Settings!$B$5,2)) -> 57.12 | AJ4: B | AK4: C | AL4: Owned: USACE standby = 0.5 x DEPR + FCCM, max 40 hr/wk [USACE-EP]; with only an all-in rate use Caltrans delay factor x rate, max 8 hr/day & 40 hr/wk [CALT-2627]: no class factor captured, use 0.10-0.22 band (inference). Rental: accrues by calendar period. FEMA: not eligible unless intermittent use [FEMA-PG]. | AM4: lowboy-legal | AN4: 20640 | AP4: N | AQ4: =IFERROR(IF(AND(INDEX(Mob_Demob!$D$6:$D$14,MATCH(AM4,Mob_Demob!$A$6:$A$14,0))="",INDEX(Mob_Demob!$G$6:$G$14,MATCH(AM4,Mob_Demob!$A$6:$A$14,0))=""),"",ROUND(MAX(N(INDEX(Mob_Demob!$G$6:$G$14,MATCH(AM4,Mob_Demob!$A$6:$A$14,0))),N(INDEX(Mob_Demob!$D$6:$D$14,MATCH(AM4,Mob_Demob!$A$6:$A$14,0)))*Settings!$B$6)+IF(AP4="Y",N(INDEX(Mob_Demob!$I$6:$I$14,MATCH(AM4,Mob_Demob!$A$6:$A$14,0)))*Settings!$B$19,0)+N(INDEX(Mob_Demob!$L$6:$L$14,MATCH(AM4,Mob_Demob!$A$6:$A$14,0)))*N(INDEX(Mob_Demob!$K$6:$K$14,MATCH(AM4,Mob_Demob!$A$6:$A$14,0)))*Settings!$B$6+N(INDEX(Mob_Demob!$M$6:$M$14,MATCH(AM4,Mob_Demob!$A$6:$A$14,0)))*N(INDEX(Mob_Demob!$N$6:$N$14,MATCH(AM4,Mob_Demob!$A$6:$A$14,0))),0)),"") -> 550 | AR4: =IF(AQ4="","",ROUND(AQ4*Settings!$B$18,0)) -> 550 | AS4: EW-STRIP,EW-PUSH-100,EW-PUSH-200,EW-SPREAD,EW-RGRADE | AT4: Operating weight given only as 20,000-24,000 lb class band (rental notes); transport class set manually. Rounded half-up (Excel rule) in revision; may differ by 1 from the notes table, which used banker's rounding. Rent: Median of 3 sources (W 906/2629/7623; C 875/2175/5412; R 850/2850/6900). Class mapping D39->D3, DD100/130->D3 per notes. Ex-fuel (C) = FEMA incl-fuel rate - Fuel_gal_hr_med x diesel back-out price (Settings B5).
A5: DZ-CRAWL-D4 | B5: Earthwork | C5: Crawler dozer | D5: Medium (Cat D4-D7) | E5: D4 class (~130 hp, ~30k lb) | F5: Net HP | G5: 130 | H5: hp | I5: Cat D4 (formerly D6K2); Komatsu D51EX/PX | J5: 29259 | K5: 130 | N5: diesel | O5: Operating Engineer - heavy equip. group (per WD) | P5: day/wk/4wk | Q5: 1142 | R5: 3062 | S5: 8302 | T5: 7075 | U5: 9529 | V5: bare | Y5: W25;C25 | Z5: 2025-2026 | AA5: A | AB5: 8252 | AC5: 86.7 | AD5: FEMA 2025 | AE5: 2.19 | AF5: 2.85 | AG5: 3.5 | AH5: Cat VisionLink Dec 2022, model D4-16 [CATFUEL22] | AI5: =IF(OR(AC5="",AF5="",Settings!$B$5=""),"",ROUND(AC5-AF5*Settings!$B$5,2)) -> 76.27 | AJ5: B | AK5: C | AL5: Owned: USACE standby = 0.5 x DEPR + FCCM, max 40 hr/wk [USACE-EP]; with only an all-in rate use Caltrans delay factor x rate, max 8 hr/day & 40 hr/wk [CALT-2627]: no class factor captured, use 0.10-0.22 band (inference). Rental: accrues by calendar period. FEMA: not eligible unless intermittent use [FEMA-PG]. | AM5: lowboy-legal | AN5: 29259 | AP5: N | AQ5: =IFERROR(IF(AND(INDEX(Mob_Demob!$D$6:$D$14,MATCH(AM5,Mob_Demob!$A$6:$A$14,0))="",INDEX(Mob_Demob!$G$6:$G$14,MATCH(AM5,Mob_Demob!$A$6:$A$14,0))=""),"",ROUND(MAX(N(INDEX(Mob_Demob!$G$6:$G$14,MATCH(AM5,Mob_Demob!$A$6:$A$14,0))),N(INDEX(Mob_Demob!$D$6:$D$14,MATCH(AM5,Mob_Demob!$A$6:$A$14,0)))*Settings!$B$6)+IF(AP5="Y",N(INDEX(Mob_Demob!$I$6:$I$14,MATCH(AM5,Mob_Demob!$A$6:$A$14,0)))*Settings!$B$19,0)+N(INDEX(Mob_Demob!$L$6:$L$14,MATCH(AM5,Mob_Demob!$A$6:$A$14,0)))*N(INDEX(Mob_Demob!$K$6:$K$14,MATCH(AM5,Mob_Demob!$A$6:$A$14,0)))*Settings!$B$6+N(INDEX(Mob_Demob!$M$6:$M$14,MATCH(AM5,Mob_Demob!$A$6:$A$14,0)))*N(INDEX(Mob_Demob!$N$6:$N$14,MATCH(AM5,Mob_Demob!$A$6:$A$14,0))),0)),"") -> 550 | AR5: =IF(AQ5="","",ROUND(AQ5*Settings!$B$18,0)) -> 550 | AS5: EW-CLR-MED,EW-STRIP,EW-PUSH-100,EW-PUSH-200,EW-SPREAD,EW-RGRADE | AT5: Rent: Median (=mean) of 2 sources: W 1133/3286/9529; C 1150/2838/7075. Ex-fuel (C) = FEMA incl-fuel rate - Fuel_gal_hr_med x diesel back-out price (Settings B5).
A6: DZ-CRAWL-D5 | B6: Earthwork | C6: Crawler dozer | D6: Medium (Cat D4-D7) | E6: D5 class (~170 hp, ~40k lb) | F6: Net HP | G6: 170 | H6: hp | I6: Cat D5 LGP VPAT; Komatsu D61EX/PX | J6: 42263 | K6: 170 | L6: Blade Cat D5 VPAT 4.6 yd3 (LGP VPAT 5.5; push-arm SU 5.6) | N6: diesel | O6: Operating Engineer - heavy equip. group (per WD) | P6: day/wk/4wk | Q6: 1554 | R6: 4210 | S6: 11461 | T6: 9200 | U6: 13721 | V6: bare | Y6: W25;C25 | Z6: 2025-2026 | AA6: A | AC6: =ROUND(AC5+(AC7-AC5)*(K6-K5)/(K7-K5),2) -> 109.5 | AD6: FEMA 2025 (interpolated) | AE6: 3.18 | AF6: 4.12 | AG6: 5.06 | AH6: Cat VisionLink Dec 2022, model D5-17 [CATFUEL22] | AI6: =IF(OR(AC6="",AF6="",Settings!$B$5=""),"",ROUND(AC6-AF6*Settings!$B$5,2)) -> 94.42 | AJ6: C | AK6: C | AL6: Owned: USACE standby = 0.5 x DEPR + FCCM, max 40 hr/wk [USACE-EP]; with only an all-in rate use Caltrans delay factor x rate, max 8 hr/day & 40 hr/wk [CALT-2627]: no class factor captured, use 0.10-0.22 band (inference). Rental: accrues by calendar period. FEMA: not eligible unless intermittent use [FEMA-PG]. | AM6: lowboy-legal | AN6: 42263 | AP6: N | AQ6: =IFERROR(IF(AND(INDEX(Mob_Demob!$D$6:$D$14,MATCH(AM6,Mob_Demob!$A$6:$A$14,0))="",INDEX(Mob_Demob!$G$6:$G$14,MATCH(AM6,Mob_Demob!$A$6:$A$14,0))=""),"",ROUND(MAX(N(INDEX(Mob_Demob!$G$6:$G$14,MATCH(AM6,Mob_Demob!$A$6:$A$14,0))),N(INDEX(Mob_Demob!$D$6:$D$14,MATCH(AM6,Mob_Demob!$A$6:$A$14,0)))*Settings!$B$6)+IF(AP6="Y",N(INDEX(Mob_Demob!$I$6:$I$14,MATCH(AM6,Mob_Demob!$A$6:$A$14,0)))*Settings!$B$19,0)+N(INDEX(Mob_Demob!$L$6:$L$14,MATCH(AM6,Mob_Demob!$A$6:$A$14,0)))*N(INDEX(Mob_Demob!$K$6:$K$14,MATCH(AM6,Mob_Demob!$A$6:$A$14,0)))*Settings!$B$6+N(INDEX(Mob_Demob!$M$6:$M$14,MATCH(AM6,Mob_Demob!$A$6:$A$14,0)))*N(INDEX(Mob_Demob!$N$6:$N$14,MATCH(AM6,Mob_Demob!$A$6:$A$14,0))),0)),"") -> 550 | AR6: =IF(AQ6="","",ROUND(AQ6*Settings!$B$18,0)) -> 550 | AS6: EW-CLR-MED,EW-STRIP,EW-PUSH-100,EW-PUSH-200,EW-PUSH-300,EW-SPREAD,EW-RGRADE | AT6: Rounded half-up (Excel rule) in revision; may differ by 1 from the notes table, which used banker's rounding. Rent: Median (=mean) of 2 sources: W 1632/4732/13721; C 1475/3688/9200. Owned_rate_hr_incl_fuel interpolated (C) between DZ-CRAWL-D4 and DZ-CRAWL-D6 by Net HP (FEMA 2025 endpoints). Ex-fuel (C) = FEMA incl-fuel rate - Fuel_gal_hr_med x diesel back-out price (Settings B5).
A7: DZ-CRAWL-D6 | B7: Earthwork | C7: Crawler dozer | D7: Medium (Cat D4-D7) | E7: D6 class (~215-240 hp, ~50k lb) | F7: Net HP | G7: 215 | H7: hp | I7: Cat D6; Komatsu D71PX | J7: 50733 | K7: 215 | L7: Blade Cat D6 SU 7.5 yd3 (VPAT 5.4; angle 5.5; LGP-36 S 5.0) | N7: diesel | O7: Operating Engineer - heavy equip. group (per WD) | P7: day/wk/4wk | Q7: 2111 | R7: 5730 | S7: 15656 | T7: 12000 | U7: 19312 | V7: bare | Y7: W25;C25 | Z7: 2025-2026 | AA7: A | AB7: 8253 | AC7: 135.15 | AD7: FEMA 2025 | AE7: 3.74 | AF7: 4.82 | AG7: 5.9 | AH7: Cat VisionLink Dec 2022, model D6-20 [CATFUEL22] | AI7: =IF(OR(AC7="",AF7="",Settings!$B$5=""),"",ROUND(AC7-AF7*Settings!$B$5,2)) -> 117.51 | AJ7: B | AK7: C | AL7: Owned: USACE standby = 0.5 x DEPR + FCCM, max 40 hr/wk [USACE-EP]; with only an all-in rate use Caltrans delay factor x rate, max 8 hr/day & 40 hr/wk [CALT-2627]: no class factor captured, use 0.10-0.22 band (inference). Rental: accrues by calendar period. FEMA: not eligible unless intermittent use [FEMA-PG]. | AM7: lowboy-legal | AN7: 50733 | AP7: maybe | AQ7: =IFERROR(IF(AND(INDEX(Mob_Demob!$D$6:$D$14,MATCH(AM7,Mob_Demob!$A$6:$A$14,0))="",INDEX(Mob_Demob!$G$6:$G$14,MATCH(AM7,Mob_Demob!$A$6:$A$14,0))=""),"",ROUND(MAX(N(INDEX(Mob_Demob!$G$6:$G$14,MATCH(AM7,Mob_Demob!$A$6:$A$14,0))),N(INDEX(Mob_Demob!$D$6:$D$14,MATCH(AM7,Mob_Demob!$A$6:$A$14,0)))*Settings!$B$6)+IF(AP7="Y",N(INDEX(Mob_Demob!$I$6:$I$14,MATCH(AM7,Mob_Demob!$A$6:$A$14,0)))*Settings!$B$19,0)+N(INDEX(Mob_Demob!$L$6:$L$14,MATCH(AM7,Mob_Demob!$A$6:$A$14,0)))*N(INDEX(Mob_Demob!$K$6:$K$14,MATCH(AM7,Mob_Demob!$A$6:$A$14,0)))*Settings!$B$6+N(INDEX(Mob_Demob!$M$6:$M$14,MATCH(AM7,Mob_Demob!$A$6:$A$14,0)))*N(INDEX(Mob_Demob!$N$6:$N$14,MATCH(AM7,Mob_Demob!$A$6:$A$14,0))),0)),"") -> 550 | AR7: =IF(AQ7="","",ROUND(AQ7*Settings!$B$18,0)) -> 550 | AS7: EW-CLR-MED,EW-STRIP,EW-PUSH-100,EW-PUSH-200,EW-PUSH-300,EW-SPREAD,EW-RGRADE | AT7: Rent: Median (=mean) of 2 sources: W D6/D6 LGP avg 2296/6659/19312; C D71PX 1925/4800/12000. Ex-fuel (C) = FEMA incl-fuel rate - Fuel_gal_hr_med x diesel back-out price (Settings B5).
A8: DZ-CRAWL-D6-XE | B8: Earthwork | C8: Crawler dozer | D8: Medium - electric drive (XE) | E8: D6 XE (215 hp) | F8: Net HP | G8: 215 | H8: hp | I8: Cat D6 XE | J8: 51333 | K8: 215 | N8: hybrid | O8: Operating Engineer - heavy equip. group (per WD) | P8: day/wk/4wk | V8: bare | AA8: D | AE8: 3.59 | AF8: 4.6 | AG8: 5.61 | AH8: Cat VisionLink Dec 2022, model D6-20 XE [CATFUEL22] | AJ8: D | AK8: D | AL8: Owned: USACE standby = 0.5 x DEPR + FCCM, max 40 hr/wk [USACE-EP]; with only an all-in rate use Caltrans delay factor x rate, max 8 hr/day & 40 hr/wk [CALT-2627]: no class factor captured, use 0.10-0.22 band (inference). Rental: accrues by calendar period. FEMA: not eligible unless intermittent use [FEMA-PG]. | AM8: lowboy-legal | AN8: 51333 | AP8: maybe | AQ8: =IFERROR(IF(AND(INDEX(Mob_Demob!$D$6:$D$14,MATCH(AM8,Mob_Demob!$A$6:$A$14,0))="",INDEX(Mob_Demob!$G$6:$G$14,MATCH(AM8,Mob_Demob!$A$6:$A$14,0))=""),"",ROUND(MAX(N(INDEX(Mob_Demob!$G$6:$G$14,MATCH(AM8,Mob_Demob!$A$6:$A$14,0))),N(INDEX(Mob_Demob!$D$6:$D$14,MATCH(AM8,Mob_Demob!$A$6:$A$14,0)))*Settings!$B$6)+IF(AP8="Y",N(INDEX(Mob_Demob!$I$6:$I$14,MATCH(AM8,Mob_Demob!$A$6:$A$14,0)))*Settings!$B$19,0)+N(INDEX(Mob_Demob!$L$6:$L$14,MATCH(AM8,Mob_Demob!$A$6:$A$14,0)))*N(INDEX(Mob_Demob!$K$6:$K$14,MATCH(AM8,Mob_Demob!$A$6:$A$14,0)))*Settings!$B$6+N(INDEX(Mob_Demob!$M$6:$M$14,MATCH(AM8,Mob_Demob!$A$6:$A$14,0)))*N(INDEX(Mob_Demob!$N$6:$N$14,MATCH(AM8,Mob_Demob!$A$6:$A$14,0))),0)),"") -> 550 | AR8: =IF(AQ8="","",ROUND(AQ8*Settings!$B$18,0)) -> 550 | AS8: EW-STRIP,EW-PUSH-100,EW-PUSH-200,EW-PUSH-300,EW-SPREAD,EW-RGRADE | AT8: Diesel-electric drive. No rate source; D6 class row is the nearest priced class. | AU8: Needs rate; Needs rate (rental); Needs rate (owned)
A9: DZ-CRAWL-D6-LGP | B9: Earthwork | C9: Crawler dozer | D9: Medium - LGP (low ground pressure) | E9: D6 LGP | F9: Track variant | G9: LGP | I9: Cat D6 LGP | L9: Blade Cat D6 LGP SU 7.6 yd3 (LGP VPAT 5.9-6.5) | N9: diesel | O9: Operating Engineer - heavy equip. group (per WD) | P9: day/wk/4wk | Q9: 2372 | R9: 6878 | S9: 19947 | V9: bare | Y9: W25 | Z9: 2025 | AA9: B | AJ9: D | AK9: D | AL9: Owned: USACE standby = 0.5 x DEPR + FCCM, max 40 hr/wk [USACE-EP]; with only an all-in rate use Caltrans delay factor x rate, max 8 hr/day & 40 hr/wk [CALT-2627]: no class factor captured, use 0.10-0.22 band (inference). Rental: accrues by calendar period. FEMA: not eligible unless intermittent use [FEMA-PG]. | AM9: lowboy-legal | AP9: maybe | AQ9: =IFERROR(IF(AND(INDEX(Mob_Demob!$D$6:$D$14,MATCH(AM9,Mob_Demob!$A$6:$A$14,0))="",INDEX(Mob_Demob!$G$6:$G$14,MATCH(AM9,Mob_Demob!$A$6:$A$14,0))=""),"",ROUND(MAX(N(INDEX(Mob_Demob!$G$6:$G$14,MATCH(AM9,Mob_Demob!$A$6:$A$14,0))),N(INDEX(Mob_Demob!$D$6:$D$14,MATCH(AM9,Mob_Demob!$A$6:$A$14,0)))*Settings!$B$6)+IF(AP9="Y",N(INDEX(Mob_Demob!$I$6:$I$14,MATCH(AM9,Mob_Demob!$A$6:$A$14,0)))*Settings!$B$19,0)+N(INDEX(Mob_Demob!$L$6:$L$14,MATCH(AM9,Mob_Demob!$A$6:$A$14,0)))*N(INDEX(Mob_Demob!$K$6:$K$14,MATCH(AM9,Mob_Demob!$A$6:$A$14,0)))*Settings!$B$6+N(INDEX(Mob_Demob!$M$6:$M$14,MATCH(AM9,Mob_Demob!$A$6:$A$14,0)))*N(INDEX(Mob_Demob!$N$6:$N$14,MATCH(AM9,Mob_Demob!$A$6:$A$14,0))),0)),"") -> 550 | AR9: =IF(AQ9="","",ROUND(AQ9*Settings!$B$18,0)) -> 550 | AS9: EW-STRIP,EW-PUSH-100,EW-SPREAD,EW-RGRADE | AT9: HP/weight for LGP not in notes. Rent: Wheeler only. | AU9: Needs fuel gal/hr; Needs rate (owned)
A10: DZ-CRAWL-D7 | B10: Earthwork | C10: Crawler dozer | D10: Medium (Cat D4-D7) | E10: D7 class (~265 hp) | F10: Net HP | G10: 265 | H10: hp | I10: Cat D7 (formerly D7E) | J10: 65644 | K10: 265 | L10: Blade Cat D7 (Tier 3, MX page) SU 9.7 yd3 (S 8.1) | N10: diesel | O10: Operating Engineer - heavy equip. group (per WD) | P10: day/wk/4wk | Q10: 2973 | R10: 8623 | S10: 25006 | V10: bare | Y10: W25 | Z10: 2025 | AA10: B | AC10: =ROUND(AC7+(AC11-AC7)*(K10-K7)/(K11-K7),2) -> 161.61 | AD10: FEMA 2025 (interpolated) | AE10: 4.4 | AF10: 5.71 | AG10: 7.02 | AH10: Cat VisionLink Dec 2022, model D7-17 [CATFUEL22] | AI10: =IF(OR(AC10="",AF10="",Settings!$B$5=""),"",ROUND(AC10-AF10*Settings!$B$5,2)) -> 140.71 | AJ10: C | AK10: C | AL10: Owned: USACE standby = 0.5 x DEPR + FCCM, max 40 hr/wk [USACE-EP]; with only an all-in rate use Caltrans delay factor x rate, max 8 hr/day & 40 hr/wk [CALT-2627]: no class factor captured, use 0.10-0.22 band (inference). Rental: accrues by calendar period. FEMA: not eligible unless intermittent use [FEMA-PG]. | AM10: lowboy-permitted | AN10: 65644 | AP10: Y | AQ10: =IFERROR(IF(AND(INDEX(Mob_Demob!$D$6:$D$14,MATCH(AM10,Mob_Demob!$A$6:$A$14,0))="",INDEX(Mob_Demob!$G$6:$G$14,MATCH(AM10,Mob_Demob!$A$6:$A$14,0))=""),"",ROUND(MAX(N(INDEX(Mob_Demob!$G$6:$G$14,MATCH(AM10,Mob_Demob!$A$6:$A$14,0))),N(INDEX(Mob_Demob!$D$6:$D$14,MATCH(AM10,Mob_Demob!$A$6:$A$14,0)))*Settings!$B$6)+IF(AP10="Y",N(INDEX(Mob_Demob!$I$6:$I$14,MATCH(AM10,Mob_Demob!$A$6:$A$14,0)))*Settings!$B$19,0)+N(INDEX(Mob_Demob!$L$6:$L$14,MATCH(AM10,Mob_Demob!$A$6:$A$14,0)))*N(INDEX(Mob_Demob!$K$6:$K$14,MATCH(AM10,Mob_Demob!$A$6:$A$14,0)))*Settings!$B$6+N(INDEX(Mob_Demob!$M$6:$M$14,MATCH(AM10,Mob_Demob!$A$6:$A$14,0)))*N(INDEX(Mob_Demob!$N$6:$N$14,MATCH(AM10,Mob_Demob!$A$6:$A$14,0))),0)),"") -> 1800 | AR10: =IF(AQ10="","",ROUND(AQ10*Settings!$B$18,0)) -> 1800 | AS10: EW-CLR-MED,EW-STRIP,EW-PUSH-100,EW-PUSH-200,EW-PUSH-300,EW-SPREAD,EW-RGRADE | AT10: Transport set to lowboy-permitted: ~65,600 lb machine + tractor/lowboy exceeds 80,000 lb gross (notes' 36 t excavator reasoning). Rent: Wheeler only. Owned_rate_hr_incl_fuel interpolated (C) between DZ-CRAWL-D6 and DZ-CRAWL-D8 by Net HP (FEMA 2025 endpoints). Ex-fuel (C) = FEMA incl-fuel rate - Fuel_gal_hr_med x diesel back-out price (Settings B5).
A11: DZ-CRAWL-D8 | B11: Earthwork | C11: Crawler dozer | D11: Large (Cat D8-D11) | E11: D8 class (~363 hp) | F11: Net HP | G11: 363 | H11: hp | I11: Cat D8 (D8T) | J11: 87083 | K11: 363 | L11: Blade Cat D8 SU 13.47 yd3 (LGP SU 12.9) | N11: diesel | O11: Operating Engineer - heavy equip. group (per WD) | P11: day/wk/4wk | Q11: 4170 | R11: 12092 | S11: 35066 | V11: bare | Y11: W25 | Z11: 2025 | AA11: B | AB11: 8254 | AC11: 213.48 | AD11: FEMA 2025 | AE11: 6.54 | AF11: 8.59 | AG11: 10.64 | AH11: Cat VisionLink Dec 2022, model D8-21 / D8T [CATFUEL22] | AI11: =IF(OR(AC11="",AF11="",Settings!$B$5=""),"",ROUND(AC11-AF11*Settings!$B$5,2)) -> 182.04 | AJ11: B | AK11: C | AL11: Owned: USACE standby = 0.5 x DEPR + FCCM, max 40 hr/wk [USACE-EP]; with only an all-in rate use Caltrans delay factor x rate, max 8 hr/day & 40 hr/wk [CALT-2627]: no class factor captured, use 0.10-0.22 band (inference). Rental: accrues by calendar period. FEMA: not eligible unless intermittent use [FEMA-PG]. | AM11: lowboy-permitted | AN11: 87083 | AP11: Y | AQ11: =IFERROR(IF(AND(INDEX(Mob_Demob!$D$6:$D$14,MATCH(AM11,Mob_Demob!$A$6:$A$14,0))="",INDEX(Mob_Demob!$G$6:$G$14,MATCH(AM11,Mob_Demob!$A$6:$A$14,0))=""),"",ROUND(MAX(N(INDEX(Mob_Demob!$G$6:$G$14,MATCH(AM11,Mob_Demob!$A$6:$A$14,0))),N(INDEX(Mob_Demob!$D$6:$D$14,MATCH(AM11,Mob_Demob!$A$6:$A$14,0)))*Settings!$B$6)+IF(AP11="Y",N(INDEX(Mob_Demob!$I$6:$I$14,MATCH(AM11,Mob_Demob!$A$6:$A$14,0)))*Settings!$B$19,0)+N(INDEX(Mob_Demob!$L$6:$L$14,MATCH(AM11,Mob_Demob!$A$6:$A$14,0)))*N(INDEX(Mob_Demob!$K$6:$K$14,MATCH(AM11,Mob_Demob!$A$6:$A$14,0)))*Settings!$B$6+N(INDEX(Mob_Demob!$M$6:$M$14,MATCH(AM11,Mob_Demob!$A$6:$A$14,0)))*N(INDEX(Mob_Demob!$N$6:$N$14,MATCH(AM11,Mob_Demob!$A$6:$A$14,0))),0)),"") -> 1800 | AR11: =IF(AQ11="","",ROUND(AQ11*Settings!$B$18,0)) -> 1800 | AS11: EW-CLR-HVY,EW-PUSH-100,EW-PUSH-200,EW-PUSH-300,EW-SPREAD,EW-RIP | AT11: Ziegler lists D8 as Medium, Carter as Large; Large used (Carter rename grouping). Rent: Wheeler only. Ex-fuel (C) = FEMA incl-fuel rate - Fuel_gal_hr_med x diesel back-out price (Settings B5).
A12: DZ-CRAWL-D9 | B12: Earthwork | C12: Crawler dozer | D12: Large (Cat D8-D11) | E12: D9 class (~452 hp) | F12: Net HP | G12: 452 | H12: hp | I12: Cat D9 | J12: 110205 | K12: 452 | L12: Blade Cat D9 SU 17.8 yd3 (U 21.7) | N12: diesel | O12: Operating Engineer - heavy equip. group (per WD) | P12: day/wk/4wk | V12: bare | AA12: D | AB12: 8255 | AC12: 360.3 | AD12: FEMA 2025 | AE12: 7.93 | AF12: 10.38 | AG12: 12.82 | AH12: Cat VisionLink Dec 2022, model D9-07 [CATFUEL22] | AI12: =IF(OR(AC12="",AF12="",Settings!$B$5=""),"",ROUND(AC12-AF12*Settings!$B$5,2)) -> 322.31 | AJ12: B | AK12: C | AL12: Owned: USACE standby = 0.5 x DEPR + FCCM, max 40 hr/wk [USACE-EP]; with only an all-in rate use Caltrans delay factor x rate, max 8 hr/day & 40 hr/wk [CALT-2627]: no class factor captured, use 0.10-0.22 band (inference). Rental: accrues by calendar period. FEMA: not eligible unless intermittent use [FEMA-PG]. | AM12: multi-axle-heavy | AN12: 110205 | AP12: Y | AQ12: =IFERROR(IF(AND(INDEX(Mob_Demob!$D$6:$D$14,MATCH(AM12,Mob_Demob!$A$6:$A$14,0))="",INDEX(Mob_Demob!$G$6:$G$14,MATCH(AM12,Mob_Demob!$A$6:$A$14,0))=""),"",ROUND(MAX(N(INDEX(Mob_Demob!$G$6:$G$14,MATCH(AM12,Mob_Demob!$A$6:$A$14,0))),N(INDEX(Mob_Demob!$D$6:$D$14,MATCH(AM12,Mob_Demob!$A$6:$A$14,0)))*Settings!$B$6)+IF(AP12="Y",N(INDEX(Mob_Demob!$I$6:$I$14,MATCH(AM12,Mob_Demob!$A$6:$A$14,0)))*Settings!$B$19,0)+N(INDEX(Mob_Demob!$L$6:$L$14,MATCH(AM12,Mob_Demob!$A$6:$A$14,0)))*N(INDEX(Mob_Demob!$K$6:$K$14,MATCH(AM12,Mob_Demob!$A$6:$A$14,0)))*Settings!$B$6+N(INDEX(Mob_Demob!$M$6:$M$14,MATCH(AM12,Mob_Demob!$A$6:$A$14,0)))*N(INDEX(Mob_Demob!$N$6:$N$14,MATCH(AM12,Mob_Demob!$A$6:$A$14,0))),0)),"") -> 1913 | AR12: =IF(AQ12="","",ROUND(AQ12*Settings!$B$18,0)) -> 1913 | AS12: EW-CLR-HVY,EW-PUSH-100,EW-PUSH-200,EW-PUSH-300,EW-RIP | AT12: Weight not in notes; transport set per mob notes ('D9+' multi-axle). Weight from cat.com (D9 110,205-111,362 lb) [CAT-DOZ-PG]. Ex-fuel (C) = FEMA incl-fuel rate - Fuel_gal_hr_med x diesel back-out price (Settings B5). | AU12: Needs rate (rental)
A13: DZ-CRAWL-D10 | B13: Earthwork | C13: Crawler dozer | D13: Large (Cat D8-D11) | E13: D10 class (~602 hp) | F13: Net HP | G13: 602 | H13: hp | I13: Cat D10 (D10T2) | J13: 154888 | K13: 602 | L13: Blade Cat D10 10SU 24.2 yd3 (10U 28.7) | N13: diesel | O13: Operating Engineer - heavy equip. group (per WD) | P13: day/wk/4wk | V13: bare | AA13: D | AC13: =ROUND(AC12+(AC14-AC12)*(K13-K12)/(K14-K12),2) -> 431.85 | AD13: FEMA 2025 (interpolated) | AE13: 11.46 | AF13: 15.09 | AG13: 18.73 | AH13: Cat VisionLink Dec 2022, model D10T2 [CATFUEL22] | AI13: =IF(OR(AC13="",AF13="",Settings!$B$5=""),"",ROUND(AC13-AF13*Settings!$B$5,2)) -> 376.62 | AJ13: C | AK13: C | AL13: Owned: USACE standby = 0.5 x DEPR + FCCM, max 40 hr/wk [USACE-EP]; with only an all-in rate use Caltrans delay factor x rate, max 8 hr/day & 40 hr/wk [CALT-2627]: no class factor captured, use 0.10-0.22 band (inference). Rental: accrues by calendar period. FEMA: not eligible unless intermittent use [FEMA-PG]. | AM13: multi-axle-heavy | AN13: 154888 | AP13: Y | AQ13: =IFERROR(IF(AND(INDEX(Mob_Demob!$D$6:$D$14,MATCH(AM13,Mob_Demob!$A$6:$A$14,0))="",INDEX(Mob_Demob!$G$6:$G$14,MATCH(AM13,Mob_Demob!$A$6:$A$14,0))=""),"",ROUND(MAX(N(INDEX(Mob_Demob!$G$6:$G$14,MATCH(AM13,Mob_Demob!$A$6:$A$14,0))),N(INDEX(Mob_Demob!$D$6:$D$14,MATCH(AM13,Mob_Demob!$A$6:$A$14,0)))*Settings!$B$6)+IF(AP13="Y",N(INDEX(Mob_Demob!$I$6:$I$14,MATCH(AM13,Mob_Demob!$A$6:$A$14,0)))*Settings!$B$19,0)+N(INDEX(Mob_Demob!$L$6:$L$14,MATCH(AM13,Mob_Demob!$A$6:$A$14,0)))*N(INDEX(Mob_Demob!$K$6:$K$14,MATCH(AM13,Mob_Demob!$A$6:$A$14,0)))*Settings!$B$6+N(INDEX(Mob_Demob!$M$6:$M$14,MATCH(AM13,Mob_Demob!$A$6:$A$14,0)))*N(INDEX(Mob_Demob!$N$6:$N$14,MATCH(AM13,Mob_Demob!$A$6:$A$14,0))),0)),"") -> 1913 | AR13: =IF(AQ13="","",ROUND(AQ13*Settings!$B$18,0)) -> 1913 | AS13: EW-PUSH-100,EW-PUSH-200,EW-PUSH-300,EW-RIP | AT13: Rental quoted on request only (Wheeler). Weight from cat.com (D9 110,205-111,362 lb) [CAT-DOZ-PG]. Owned_rate_hr_incl_fuel interpolated (C) between DZ-CRAWL-D9 and DZ-CRAWL-D11 by Net HP (FEMA 2025 endpoints). Ex-fuel (C) = FEMA incl-fuel rate - Fuel_gal_hr_med x diesel back-out price (Settings B5). | AU13: Needs rate (rental)
A14: DZ-CRAWL-D11 | B14: Earthwork | C14: Crawler dozer | D14: Large (Cat D8-D11) | E14: D11 class (~850 hp) | F14: Net HP | G14: 850 | H14: hp | I14: Cat D11 | J14: 235507 | K14: 850 | L14: Blade Cat D11 SU 35.6 yd3 (U 45; reclamation U 55; carrydozer 57) | N14: diesel | O14: Operating Engineer - heavy equip. group (per WD) | P14: day/wk/4wk | V14: bare | AA14: D | AB14: 8256 | AC14: 550.14 | AD14: FEMA 2025 | AE14: 15.45 | AF14: 20.52 | AG14: 25.59 | AH14: Cat VisionLink Dec 2022, model D11-07 [CATFUEL22] | AI14: =IF(OR(AC14="",AF14="",Settings!$B$5=""),"",ROUND(AC14-AF14*Settings!$B$5,2)) -> 475.04 | AJ14: B | AK14: C | AL14: Owned: USACE standby = 0.5 x DEPR + FCCM, max 40 hr/wk [USACE-EP]; with only an all-in rate use Caltrans delay factor x rate, max 8 hr/day & 40 hr/wk [CALT-2627]: no class factor captured, use 0.10-0.22 band (inference). Rental: accrues by calendar period. FEMA: not eligible unless intermittent use [FEMA-PG]. | AM14: multi-axle-heavy | AN14: 235507 | AP14: Y | AQ14: =IFERROR(IF(AND(INDEX(Mob_Demob!$D$6:$D$14,MATCH(AM14,Mob_Demob!$A$6:$A$14,0))="",INDEX(Mob_Demob!$G$6:$G$14,MATCH(AM14,Mob_Demob!$A$6:$A$14,0))=""),"",ROUND(MAX(N(INDEX(Mob_Demob!$G$6:$G$14,MATCH(AM14,Mob_Demob!$A$6:$A$14,0))),N(INDEX(Mob_Demob!$D$6:$D$14,MATCH(AM14,Mob_Demob!$A$6:$A$14,0)))*Settings!$B$6)+IF(AP14="Y",N(INDEX(Mob_Demob!$I$6:$I$14,MATCH(AM14,Mob_Demob!$A$6:$A$14,0)))*Settings!$B$19,0)+N(INDEX(Mob_Demob!$L$6:$L$14,MATCH(AM14,Mob_Demob!$A$6:$A$14,0)))*N(INDEX(Mob_Demob!$K$6:$K$14,MATCH(AM14,Mob_Demob!$A$6:$A$14,0)))*Settings!$B$6+N(INDEX(Mob_Demob!$M$6:$M$14,MATCH(AM14,Mob_Demob!$A$6:$A$14,0)))*N(INDEX(Mob_Demob!$N$6:$N$14,MATCH(AM14,Mob_Demob!$A$6:$A$14,0))),0)),"") -> 1913 | AR14: =IF(AQ14="","",ROUND(AQ14*Settings!$B$18,0)) -> 1913 | AS14: EW-PUSH-100,EW-PUSH-200,EW-PUSH-300,EW-RIP | AT14: Rental quoted on request only (Wheeler). Weight from cat.com (D9 110,205-111,362 lb) [CAT-DOZ-PG]. Ex-fuel (C) = FEMA incl-fuel rate - Fuel_gal_hr_med x diesel back-out price (Settings B5). | AU14: Needs rate (rental)
A15: DZ-WHEEL-814 | B15: Earthwork | C15: Wheel dozer | D15: Rubber-tired dozer | E15: Cat 814 class (~249 hp) | F15: Net HP | G15: 249 | H15: hp | I15: Cat 814 | K15: 249 | N15: diesel | O15: Operating Engineer - heavy equip. group (per WD) | P15: day/wk/4wk | V15: bare | AA15: D | AB15: 8260 | AC15: 101.21 | AD15: FEMA 2025 | AE15: =ROUND(K15*Settings!$B$11*Settings!$B$13,2) -> 4.24 | AF15: =ROUND(K15*Settings!$B$11*Settings!$B$14,2) -> 5.57 | AG15: =ROUND(K15*Settings!$B$11*Settings!$B$15,2) -> 7.26 | AH15: Derived (C): Net_HP x 0.0486 diesel gal/bhp-hr x load factor 0.35/0.46/0.60 [USACE-EP] | AI15: =IF(OR(AC15="",AF15="",Settings!$B$5=""),"",ROUND(AC15-AF15*Settings!$B$5,2)) -> 80.82 | AJ15: B | AK15: C | AL15: Owned: USACE standby = 0.5 x DEPR + FCCM, max 40 hr/wk [USACE-EP]; with only an all-in rate use Caltrans delay factor x rate, max 8 hr/day & 40 hr/wk [CALT-2627]: no class factor captured, use 0.10-0.22 band (inference). Rental: accrues by calendar period. FEMA: not eligible unless intermittent use [FEMA-PG]. | AM15: lowboy-permitted | AP15: Y | AQ15: =IFERROR(IF(AND(INDEX(Mob_Demob!$D$6:$D$14,MATCH(AM15,Mob_Demob!$A$6:$A$14,0))="",INDEX(Mob_Demob!$G$6:$G$14,MATCH(AM15,Mob_Demob!$A$6:$A$14,0))=""),"",ROUND(MAX(N(INDEX(Mob_Demob!$G$6:$G$14,MATCH(AM15,Mob_Demob!$A$6:$A$14,0))),N(INDEX(Mob_Demob!$D$6:$D$14,MATCH(AM15,Mob_Demob!$A$6:$A$14,0)))*Settings!$B$6)+IF(AP15="Y",N(INDEX(Mob_Demob!$I$6:$I$14,MATCH(AM15,Mob_Demob!$A$6:$A$14,0)))*Settings!$B$19,0)+N(INDEX(Mob_Demob!$L$6:$L$14,MATCH(AM15,Mob_Demob!$A$6:$A$14,0)))*N(INDEX(Mob_Demob!$K$6:$K$14,MATCH(AM15,Mob_Demob!$A$6:$A$14,0)))*Settings!$B$6+N(INDEX(Mob_Demob!$M$6:$M$14,MATCH(AM15,Mob_Demob!$A$6:$A$14,0)))*N(INDEX(Mob_Demob!$N$6:$N$14,MATCH(AM15,Mob_Demob!$A$6:$A$14,0))),0)),"") -> 1800 | AR15: =IF(AQ15="","",ROUND(AQ15*Settings!$B$18,0)) -> 1800 | AS15: EW-PUSH-100,EW-PUSH-200,EW-SPREAD | AT15: Weight not in notes; transport class assumed permitted (verify). Fuel gal/hr derived (C): Net_HP x USACE fuel factor x load factor (Settings B11-B15). Ex-fuel (C) = FEMA incl-fuel rate - Fuel_gal_hr_med x diesel back-out price (Settings B5). | AU15: Needs rate (rental)
A16: DZ-WHEEL-824 | B16: Earthwork | C16: Wheel dozer | D16: Rubber-tired dozer | E16: Cat 824 class (~405 hp) | F16: Net HP | G16: 405 | H16: hp | I16: Cat 824 | J16: 74966 | K16: 405 | N16: diesel | O16: Operating Engineer - heavy equip. group (per WD) | P16: day/wk/4wk | V16: bare | AA16: D | AB16: 8261 | AC16: 170.28 | AD16: FEMA 2025 | AE16: =ROUND(K16*Settings!$B$11*Settings!$B$13,2) -> 6.89 | AF16: =ROUND(K16*Settings!$B$11*Settings!$B$14,2) -> 9.05 | AG16: =ROUND(K16*Settings!$B$11*Settings!$B$15,2) -> 11.81 | AH16: Derived (C): Net_HP x 0.0486 diesel gal/bhp-hr x load factor 0.35/0.46/0.60 [USACE-EP] | AI16: =IF(OR(AC16="",AF16="",Settings!$B$5=""),"",ROUND(AC16-AF16*Settings!$B$5,2)) -> 137.16 | AJ16: B | AK16: C | AL16: Owned: USACE standby = 0.5 x DEPR + FCCM, max 40 hr/wk [USACE-EP]; with only an all-in rate use Caltrans delay factor x rate, max 8 hr/day & 40 hr/wk [CALT-2627]: no class factor captured, use 0.10-0.22 band (inference). Rental: accrues by calendar period. FEMA: not eligible unless intermittent use [FEMA-PG]. | AM16: lowboy-permitted | AN16: 74966 | AP16: Y | AQ16: =IFERROR(IF(AND(INDEX(Mob_Demob!$D$6:$D$14,MATCH(AM16,Mob_Demob!$A$6:$A$14,0))="",INDEX(Mob_Demob!$G$6:$G$14,MATCH(AM16,Mob_Demob!$A$6:$A$14,0))=""),"",ROUND(MAX(N(INDEX(Mob_Demob!$G$6:$G$14,MATCH(AM16,Mob_Demob!$A$6:$A$14,0))),N(INDEX(Mob_Demob!$D$6:$D$14,MATCH(AM16,Mob_Demob!$A$6:$A$14,0)))*Settings!$B$6)+IF(AP16="Y",N(INDEX(Mob_Demob!$I$6:$I$14,MATCH(AM16,Mob_Demob!$A$6:$A$14,0)))*Settings!$B$19,0)+N(INDEX(Mob_Demob!$L$6:$L$14,MATCH(AM16,Mob_Demob!$A$6:$A$14,0)))*N(INDEX(Mob_Demob!$K$6:$K$14,MATCH(AM16,Mob_Demob!$A$6:$A$14,0)))*Settings!$B$6+N(INDEX(Mob_Demob!$M$6:$M$14,MATCH(AM16,Mob_Demob!$A$6:$A$14,0)))*N(INDEX(Mob_Demob!$N$6:$N$14,MATCH(AM16,Mob_Demob!$A$6:$A$14,0))),0)),"") -> 1800 | AR16: =IF(AQ16="","",ROUND(AQ16*Settings!$B$18,0)) -> 1800 | AS16: EW-PUSH-100,EW-PUSH-200,EW-SPREAD | AT16: Fuel gal/hr derived (C): Net_HP x USACE fuel factor x load factor (Settings B11-B15). Ex-fuel (C) = FEMA incl-fuel rate - Fuel_gal_hr_med x diesel back-out price (Settings B5). | AU16: Needs rate (rental)
A17: DZ-WHEEL-834 | B17: Earthwork | C17: Wheel dozer | D17: Rubber-tired dozer | E17: Cat 834 class (~496 hp) | F17: Net HP | G17: 496 | H17: hp | I17: Cat 834 | J17: 105271 | K17: 496 | N17: diesel | O17: Operating Engineer - heavy equip. group (per WD) | P17: day/wk/4wk | V17: bare | AA17: D | AB17: 8262 | AC17: 308.97 | AD17: FEMA 2025 | AE17: =ROUND(K17*Settings!$B$11*Settings!$B$13,2) -> 8.44 | AF17: =ROUND(K17*Settings!$B$11*Settings!$B$14,2) -> 11.09 | AG17: =ROUND(K17*Settings!$B$11*Settings!$B$15,2) -> 14.46 | AH17: Derived (C): Net_HP x 0.0486 diesel gal/bhp-hr x load factor 0.35/0.46/0.60 [USACE-EP] | AI17: =IF(OR(AC17="",AF17="",Settings!$B$5=""),"",ROUND(AC17-AF17*Settings!$B$5,2)) -> 268.38 | AJ17: B | AK17: C | AL17: Owned: USACE standby = 0.5 x DEPR + FCCM, max 40 hr/wk [USACE-EP]; with only an all-in rate use Caltrans delay factor x rate, max 8 hr/day & 40 hr/wk [CALT-2627]: no class factor captured, use 0.10-0.22 band (inference). Rental: accrues by calendar period. FEMA: not eligible unless intermittent use [FEMA-PG]. | AM17: multi-axle-heavy | AN17: 105271 | AP17: Y | AQ17: =IFERROR(IF(AND(INDEX(Mob_Demob!$D$6:$D$14,MATCH(AM17,Mob_Demob!$A$6:$A$14,0))="",INDEX(Mob_Demob!$G$6:$G$14,MATCH(AM17,Mob_Demob!$A$6:$A$14,0))=""),"",ROUND(MAX(N(INDEX(Mob_Demob!$G$6:$G$14,MATCH(AM17,Mob_Demob!$A$6:$A$14,0))),N(INDEX(Mob_Demob!$D$6:$D$14,MATCH(AM17,Mob_Demob!$A$6:$A$14,0)))*Settings!$B$6)+IF(AP17="Y",N(INDEX(Mob_Demob!$I$6:$I$14,MATCH(AM17,Mob_Demob!$A$6:$A$14,0)))*Settings!$B$19,0)+N(INDEX(Mob_Demob!$L$6:$L$14,MATCH(AM17,Mob_Demob!$A$6:$A$14,0)))*N(INDEX(Mob_Demob!$K$6:$K$14,MATCH(AM17,Mob_Demob!$A$6:$A$14,0)))*Settings!$B$6+N(INDEX(Mob_Demob!$M$6:$M$14,MATCH(AM17,Mob_Demob!$A$6:$A$14,0)))*N(INDEX(Mob_Demob!$N$6:$N$14,MATCH(AM17,Mob_Demob!$A$6:$A$14,0))),0)),"") -> 1913 | AR17: =IF(AQ17="","",ROUND(AQ17*Settings!$B$18,0)) -> 1913 | AS17: EW-PUSH-100,EW-PUSH-200,EW-SPREAD | AT17: Fuel gal/hr derived (C): Net_HP x USACE fuel factor x load factor (Settings B11-B15). Ex-fuel (C) = FEMA incl-fuel rate - Fuel_gal_hr_med x diesel back-out price (Settings B5). | AU17: Needs rate (rental)
A18: DZ-WHEEL-844 | B18: Earthwork | C18: Wheel dozer | D18: Rubber-tired dozer | E18: Cat 844 class (~732 hp) | F18: Net HP | G18: 732 | H18: hp | I18: Cat 844 | K18: 732 | N18: diesel | O18: Operating Engineer - heavy equip. group (per WD) | P18: day/wk/4wk | V18: bare | AA18: D | AB18: 8263 | AC18: 402.76 | AD18: FEMA 2025 | AE18: =ROUND(K18*Settings!$B$11*Settings!$B$13,2) -> 12.45 | AF18: =ROUND(K18*Settings!$B$11*Settings!$B$14,2) -> 16.36 | AG18: =ROUND(K18*Settings!$B$11*Settings!$B$15,2) -> 21.35 | AH18: Derived (C): Net_HP x 0.0486 diesel gal/bhp-hr x load factor 0.35/0.46/0.60 [USACE-EP] | AI18: =IF(OR(AC18="",AF18="",Settings!$B$5=""),"",ROUND(AC18-AF18*Settings!$B$5,2)) -> 342.88 | AJ18: B | AK18: C | AL18: Owned: USACE standby = 0.5 x DEPR + FCCM, max 40 hr/wk [USACE-EP]; with only an all-in rate use Caltrans delay factor x rate, max 8 hr/day & 40 hr/wk [CALT-2627]: no class factor captured, use 0.10-0.22 band (inference). Rental: accrues by calendar period. FEMA: not eligible unless intermittent use [FEMA-PG]. | AM18: multi-axle-heavy | AP18: Y | AQ18: =IFERROR(IF(AND(INDEX(Mob_Demob!$D$6:$D$14,MATCH(AM18,Mob_Demob!$A$6:$A$14,0))="",INDEX(Mob_Demob!$G$6:$G$14,MATCH(AM18,Mob_Demob!$A$6:$A$14,0))=""),"",ROUND(MAX(N(INDEX(Mob_Demob!$G$6:$G$14,MATCH(AM18,Mob_Demob!$A$6:$A$14,0))),N(INDEX(Mob_Demob!$D$6:$D$14,MATCH(AM18,Mob_Demob!$A$6:$A$14,0)))*Settings!$B$6)+IF(AP18="Y",N(INDEX(Mob_Demob!$I$6:$I$14,MATCH(AM18,Mob_Demob!$A$6:$A$14,0)))*Settings!$B$19,0)+N(INDEX(Mob_Demob!$L$6:$L$14,MATCH(AM18,Mob_Demob!$A$6:$A$14,0)))*N(INDEX(Mob_Demob!$K$6:$K$14,MATCH(AM18,Mob_Demob!$A$6:$A$14,0)))*Settings!$B$6+N(INDEX(Mob_Demob!$M$6:$M$14,MATCH(AM18,Mob_Demob!$A$6:$A$14,0)))*N(INDEX(Mob_Demob!$N$6:$N$14,MATCH(AM18,Mob_Demob!$A$6:$A$14,0))),0)),"") -> 1913 | AR18: =IF(AQ18="","",ROUND(AQ18*Settings!$B$18,0)) -> 1913 | AS18: EW-PUSH-100,EW-PUSH-200,EW-SPREAD | AT18: Weight not in notes; transport class assumed permitted (verify). Transport set to multi-axle-heavy for consistency with the lighter 834 (105,271 lb); 844 weight not in notes. Fuel gal/hr derived (C): Net_HP x USACE fuel factor x load factor (Settings B11-B15). Ex-fuel (C) = FEMA incl-fuel rate - Fuel_gal_hr_med x diesel back-out price (Settings B5). | AU18: Needs rate (rental)
A19: DZ-WHEEL-854 | B19: Earthwork | C19: Wheel dozer | D19: Rubber-tired dozer | E19: Cat 854 class (~814 hp) | F19: Net HP | G19: 814 | H19: hp | I19: Cat 854 | J19: 224647 | K19: 814 | N19: diesel | O19: Operating Engineer - heavy equip. group (per WD) | P19: day/wk/4wk | V19: bare | AA19: D | AE19: =ROUND(K19*Settings!$B$11*Settings!$B$13,2) -> 13.85 | AF19: =ROUND(K19*Settings!$B$11*Settings!$B$14,2) -> 18.2 | AG19: =ROUND(K19*Settings!$B$11*Settings!$B$15,2) -> 23.74 | AH19: Derived (C): Net_HP x 0.0486 diesel gal/bhp-hr x load factor 0.35/0.46/0.60 [USACE-EP] | AJ19: D | AK19: D | AL19: Owned: USACE standby = 0.5 x DEPR + FCCM, max 40 hr/wk [USACE-EP]; with only an all-in rate use Caltrans delay factor x rate, max 8 hr/day & 40 hr/wk [CALT-2627]: no class factor captured, use 0.10-0.22 band (inference). Rental: accrues by calendar period. FEMA: not eligible unless intermittent use [FEMA-PG]. | AM19: multi-axle-heavy | AN19: 224647 | AP19: Y | AQ19: =IFERROR(IF(AND(INDEX(Mob_Demob!$D$6:$D$14,MATCH(AM19,Mob_Demob!$A$6:$A$14,0))="",INDEX(Mob_Demob!$G$6:$G$14,MATCH(AM19,Mob_Demob!$A$6:$A$14,0))=""),"",ROUND(MAX(N(INDEX(Mob_Demob!$G$6:$G$14,MATCH(AM19,Mob_Demob!$A$6:$A$14,0))),N(INDEX(Mob_Demob!$D$6:$D$14,MATCH(AM19,Mob_Demob!$A$6:$A$14,0)))*Settings!$B$6)+IF(AP19="Y",N(INDEX(Mob_Demob!$I$6:$I$14,MATCH(AM19,Mob_Demob!$A$6:$A$14,0)))*Settings!$B$19,0)+N(INDEX(Mob_Demob!$L$6:$L$14,MATCH(AM19,Mob_Demob!$A$6:$A$14,0)))*N(INDEX(Mob_Demob!$K$6:$K$14,MATCH(AM19,Mob_Demob!$A$6:$A$14,0)))*Settings!$B$6+N(INDEX(Mob_Demob!$M$6:$M$14,MATCH(AM19,Mob_Demob!$A$6:$A$14,0)))*N(INDEX(Mob_Demob!$N$6:$N$14,MATCH(AM19,Mob_Demob!$A$6:$A$14,0))),0)),"") -> 1913 | AR19: =IF(AQ19="","",ROUND(AQ19*Settings!$B$18,0)) -> 1913 | AS19: EW-PUSH-100,EW-PUSH-200,EW-SPREAD | AT19: Fuel gal/hr derived (C): Net_HP x USACE fuel factor x load factor (Settings B11-B15). | AU19: Needs rate; Needs rate (rental); Needs rate (owned)
A20: EX-MINI-1T | B20: Earthwork | C20: Hydraulic excavator | D20: Mini/compact 1-2 t | E20: 1-2 t (<=5,000 lb) | F20: Operating weight | G20: 3913 | H20: lb | I20: Cat 300.9D (2,061 lb, 13 hp), 301.5 (3,913 lb, 21 hp), 301.7 CR, 301.8, 302 CR; Kubota K008; Bobcat E10/E20 | J20: 3913 | K20: 21 | N20: diesel | O20: Operating Engineer - light/compact group (per WD) | P20: day/wk/4wk | Q20: 237 | R20: 748 | S20: 2200 | T20: 1665 | U20: 2913 | V20: bare | Y20: W25;B25;R25;N25;A26;DOZR-EX | Z20: 2025-2026 | AA20: A | AE20: =ROUND(K20*Settings!$B$11*Settings!$B$13,2) -> 0.36 | AF20: =ROUND(K20*Settings!$B$11*Settings!$B$14,2) -> 0.47 | AG20: =ROUND(K20*Settings!$B$11*Settings!$B$15,2) -> 0.61 | AH20: Derived (C): Net_HP x 0.0486 diesel gal/bhp-hr x load factor 0.35/0.46/0.60 [USACE-EP] | AJ20: D | AK20: D | AL20: Owned: USACE standby = 0.5 x DEPR + FCCM, max 40 hr/wk [USACE-EP]; with only an all-in rate use Caltrans delay factor x rate, max 8 hr/day & 40 hr/wk [CALT-2627]: HCECL factor 0.17 (book) / 0.16 (Sep 2026 interim). Rental: accrues by calendar period (no idle discount). FEMA: not eligible unless intermittent use [FEMA-PG]. | AM20: tilt-trailer | AN20: 3913 | AP20: N | AQ20: =IFERROR(IF(AND(INDEX(Mob_Demob!$D$6:$D$14,MATCH(AM20,Mob_Demob!$A$6:$A$14,0))="",INDEX(Mob_Demob!$G$6:$G$14,MATCH(AM20,Mob_Demob!$A$6:$A$14,0))=""),"",ROUND(MAX(N(INDEX(Mob_Demob!$G$6:$G$14,MATCH(AM20,Mob_Demob!$A$6:$A$14,0))),N(INDEX(Mob_Demob!$D$6:$D$14,MATCH(AM20,Mob_Demob!$A$6:$A$14,0)))*Settings!$B$6)+IF(AP20="Y",N(INDEX(Mob_Demob!$I$6:$I$14,MATCH(AM20,Mob_Demob!$A$6:$A$14,0)))*Settings!$B$19,0)+N(INDEX(Mob_Demob!$L$6:$L$14,MATCH(AM20,Mob_Demob!$A$6:$A$14,0)))*N(INDEX(Mob_Demob!$K$6:$K$14,MATCH(AM20,Mob_Demob!$A$6:$A$14,0)))*Settings!$B$6+N(INDEX(Mob_Demob!$M$6:$M$14,MATCH(AM20,Mob_Demob!$A$6:$A$14,0)))*N(INDEX(Mob_Demob!$N$6:$N$14,MATCH(AM20,Mob_Demob!$A$6:$A$14,0))),0)),"") -> 500 | AR20: =IF(AQ20="","",ROUND(AQ20*Settings!$B$18,0)) -> 500 | AS20: EW-TRENCH-5,EW-STRUCT,EW-BACKFILL | AT20: Representative model 301.5 (3,913 lb, 21 hp) used for weight/HP. Tail swing (zero/reduced/conventional) does not change the rate class. No FEMA code below 45 hp; not extrapolated. Tail swing: zero / minimal (<10% overhang) / conventional variants exist [BOBCAT-EX]; not priced separately by the rental sources. Max dig depth: Deere 17 P 7'2" [DEERE-RENT; CAT-EXC-PG]. Rent: Median of 6 sources (W 346/1004/2913; B 248/745/2235; R 200/750/2200; N 190/665/1665; A 300/900/2200; D 225/675/1775). Fuel gal/hr derived (C): Net_HP x USACE fuel factor x load factor (Settings B11-B15). | AU20: Needs rate (owned)
A21: EX-MINI-3T | B21: Earthwork | C21: Hydraulic excavator | D21: Mini/compact 3-4 t | E21: 3-4 t (5,000-10,000 lb) | F21: Operating weight | G21: 9867 | H21: lb | I21: Cat 302.7 CR, 303 CR, 303.5 CR, 304 (9,867 lb, 45 hp); Kubota KX033/KX040; Bobcat E26/E35/E42 | J21: 9867 | K21: 45 | L21: GP bucket 0.15 yd3 (typ; Deere 35G spec-basis bucket 0.11 m3 (0.15 yd3); single value, not a range) | N21: diesel | O21: Operating Engineer - light/compact group (per WD) | P21: day/wk/4wk | Q21: 325 | R21: 1013 | S21: 2788 | T21: 2250 | U21: 4438 | V21: bare | Y21: W25;C25;B25;R25;N25;A26;DOZR-EX | Z21: 2025-2026 | AA21: A | AE21: =ROUND(K21*Settings!$B$11*Settings!$B$13,2) -> 0.77 | AF21: =ROUND(K21*Settings!$B$11*Settings!$B$14,2) -> 1.01 | AG21: =ROUND(K21*Settings!$B$11*Settings!$B$15,2) -> 1.31 | AH21: Derived (C): Net_HP x 0.0486 diesel gal/bhp-hr x load factor 0.35/0.46/0.60 [USACE-EP] | AJ21: D | AK21: D | AL21: Owned: USACE standby = 0.5 x DEPR + FCCM, max 40 hr/wk [USACE-EP]; with only an all-in rate use Caltrans delay factor x rate, max 8 hr/day & 40 hr/wk [CALT-2627]: HCECL factor 0.17 (book) / 0.16 (Sep 2026 interim). Rental: accrues by calendar period (no idle discount). FEMA: not eligible unless intermittent use [FEMA-PG]. | AM21: tilt-trailer | AN21: 9867 | AP21: N | AQ21: =IFERROR(IF(AND(INDEX(Mob_Demob!$D$6:$D$14,MATCH(AM21,Mob_Demob!$A$6:$A$14,0))="",INDEX(Mob_Demob!$G$6:$G$14,MATCH(AM21,Mob_Demob!$A$6:$A$14,0))=""),"",ROUND(MAX(N(INDEX(Mob_Demob!$G$6:$G$14,MATCH(AM21,Mob_Demob!$A$6:$A$14,0))),N(INDEX(Mob_Demob!$D$6:$D$14,MATCH(AM21,Mob_Demob!$A$6:$A$14,0)))*Settings!$B$6)+IF(AP21="Y",N(INDEX(Mob_Demob!$I$6:$I$14,MATCH(AM21,Mob_Demob!$A$6:$A$14,0)))*Settings!$B$19,0)+N(INDEX(Mob_Demob!$L$6:$L$14,MATCH(AM21,Mob_Demob!$A$6:$A$14,0)))*N(INDEX(Mob_Demob!$K$6:$K$14,MATCH(AM21,Mob_Demob!$A$6:$A$14,0)))*Settings!$B$6+N(INDEX(Mob_Demob!$M$6:$M$14,MATCH(AM21,Mob_Demob!$A$6:$A$14,0)))*N(INDEX(Mob_Demob!$N$6:$N$14,MATCH(AM21,Mob_Demob!$A$6:$A$14,0))),0)),"") -> 500 | AR21: =IF(AQ21="","",ROUND(AQ21*Settings!$B$18,0)) -> 500 | AS21: EW-TRENCH-5,EW-STRUCT,EW-BACKFILL,UT-PIPE-WATER | AT21: Representative model Cat 304 (9,867 lb, 45 hp). FEMA 8280 (305 CR) caps at 45 hp but is mapped to the 5-6 t class; not reused here. Rounded half-up (Excel rule) in revision; may differ by 1 from the notes table, which used banker's rounding. Tail swing: zero / minimal (<10% overhang) / conventional variants exist [BOBCAT-EX]; not priced separately by the rental sources. Max dig depth: Cat 303.5 CR 110.6-122.4 in; Deere 35G 10'0"; Kubota KX040-4 11.23 ft [DEERE-RENT; CAT-EXC-PG]. Rent: Median of 7 sources (W 528/1530/4438; C 375/912/2250; B 310/930/2790; R 307/1215/3190; N 290/1012/2788; A 375/1075/2625; D 325/975/2550). Fuel gal/hr derived (C): Net_HP x USACE fuel factor x load factor (Settings B11-B15). | AU21: Needs rate (owned)
A22: EX-MINI-5T | B22: Earthwork | C22: Hydraulic excavator | D22: Mini/compact 5-6 t | E22: 5-6 t (10,000-14,000 lb) | F22: Operating weight | G22: 12688 | H22: lb | I22: Cat 305 CR (12,688 lb, 45 hp, 12 ft dig), 306 CR; Kubota KX057; Case CX55; Bobcat E50/E60 | J22: 12688 | K22: 45 | N22: diesel | O22: Operating Engineer - light/compact group (per WD) | P22: day/wk/4wk | Q22: 443 | R22: 1319 | S22: 3228 | T22: 2950 | U22: 6226 | V22: bare | Y22: W25;C25;B25;R25;N25;A26 | Z22: 2025-2026 | AA22: A | AB22: 8280 | AC22: 57.14 | AD22: FEMA 2025 | AE22: 1.15 | AF22: 1.55 | AG22: 1.94 | AH22: Cat VisionLink Dec 2022, model 305-07 CR [CATFUEL22] | AI22: =IF(OR(AC22="",AF22="",Settings!$B$5=""),"",ROUND(AC22-AF22*Settings!$B$5,2)) -> 51.47 | AJ22: B | AK22: C | AL22: Owned: USACE standby = 0.5 x DEPR + FCCM, max 40 hr/wk [USACE-EP]; with only an all-in rate use Caltrans delay factor x rate, max 8 hr/day & 40 hr/wk [CALT-2627]: HCECL factor 0.17 (book) / 0.16 (Sep 2026 interim). Rental: accrues by calendar period (no idle discount). FEMA: not eligible unless intermittent use [FEMA-PG]. | AM22: tilt-trailer | AN22: 12688 | AP22: N | AQ22: =IFERROR(IF(AND(INDEX(Mob_Demob!$D$6:$D$14,MATCH(AM22,Mob_Demob!$A$6:$A$14,0))="",INDEX(Mob_Demob!$G$6:$G$14,MATCH(AM22,Mob_Demob!$A$6:$A$14,0))=""),"",ROUND(MAX(N(INDEX(Mob_Demob!$G$6:$G$14,MATCH(AM22,Mob_Demob!$A$6:$A$14,0))),N(INDEX(Mob_Demob!$D$6:$D$14,MATCH(AM22,Mob_Demob!$A$6:$A$14,0)))*Settings!$B$6)+IF(AP22="Y",N(INDEX(Mob_Demob!$I$6:$I$14,MATCH(AM22,Mob_Demob!$A$6:$A$14,0)))*Settings!$B$19,0)+N(INDEX(Mob_Demob!$L$6:$L$14,MATCH(AM22,Mob_Demob!$A$6:$A$14,0)))*N(INDEX(Mob_Demob!$K$6:$K$14,MATCH(AM22,Mob_Demob!$A$6:$A$14,0)))*Settings!$B$6+N(INDEX(Mob_Demob!$M$6:$M$14,MATCH(AM22,Mob_Demob!$A$6:$A$14,0)))*N(INDEX(Mob_Demob!$N$6:$N$14,MATCH(AM22,Mob_Demob!$A$6:$A$14,0))),0)),"") -> 500 | AR22: =IF(AQ22="","",ROUND(AQ22*Settings!$B$18,0)) -> 500 | AS22: EW-TRENCH-5,EW-TRENCH-10,EW-STRUCT,EW-BACKFILL,UT-PIPE-WATER | AT22: Rounded half-up (Excel rule) in revision; may differ by 1 from the notes table, which used banker's rounding. Tail swing: zero / minimal (<10% overhang) / conventional variants exist [BOBCAT-EX]; not priced separately by the rental sources. Max dig depth: Cat 305 CR 134.6-144.5 in; Deere 50 P 11'7"; Bobcat E50 11.4 ft [DEERE-RENT; CAT-EXC-PG]. Rent: Median of 6 sources (W 740/2147/6226; C 488/1212/3000; B 370/1110/3330; R 410/1672/3798; N 335/1175/2950; A 475/1425/3125). Ex-fuel (C) = FEMA incl-fuel rate - Fuel_gal_hr_med x diesel back-out price (Settings B5).
A23: EX-MIDI-8T | B23: Earthwork | C23: Hydraulic excavator | D23: Midi 7-8 t (nominal 8 t) | E23: 7-8 t nominal (~15,400-19,800 lb) | F23: Operating weight | G23: 18493 | H23: lb | I23: Cat 307.5 (17,905 lb), 308 CR (18,493 lb, 69.5 hp); Komatsu PC88MR (19,225 lb); Kubota KX080; Bobcat E88 | J23: 18493 | K23: 69.5 | L23: GP bucket 0.26 yd3 (typ; Komatsu PC88MR-11 single listed bucket 0.26 yd3 (aggregator)) | N23: diesel | O23: Operating Engineer - light/compact group (per WD) | P23: day/wk/4wk | Q23: 600 | R23: 1798 | S23: 4498 | T23: 3780 | U23: 6924 | V23: bare | Y23: W25;C25;B25;R25 | Z23: 2025 | AA23: A | AC23: =ROUND(AC22+(AC25-AC22)*(K23-K22)/(K25-K22),2) -> 77.76 | AD23: FEMA 2025 (interpolated) | AE23: 0.68 | AF23: 0.95 | AG23: 1.22 | AH23: Cat VisionLink Dec 2022, model 308-07 CR [CATFUEL22] | AI23: =IF(OR(AC23="",AF23="",Settings!$B$5=""),"",ROUND(AC23-AF23*Settings!$B$5,2)) -> 74.28 | AJ23: C | AK23: C | AL23: Owned: USACE standby = 0.5 x DEPR + FCCM, max 40 hr/wk [USACE-EP]; with only an all-in rate use Caltrans delay factor x rate, max 8 hr/day & 40 hr/wk [CALT-2627]: HCECL factor 0.17 (book) / 0.16 (Sep 2026 interim). Rental: accrues by calendar period (no idle discount). FEMA: not eligible unless intermittent use [FEMA-PG]. | AM23: tilt-trailer | AN23: 18493 | AP23: N | AQ23: =IFERROR(IF(AND(INDEX(Mob_Demob!$D$6:$D$14,MATCH(AM23,Mob_Demob!$A$6:$A$14,0))="",INDEX(Mob_Demob!$G$6:$G$14,MATCH(AM23,Mob_Demob!$A$6:$A$14,0))=""),"",ROUND(MAX(N(INDEX(Mob_Demob!$G$6:$G$14,MATCH(AM23,Mob_Demob!$A$6:$A$14,0))),N(INDEX(Mob_Demob!$D$6:$D$14,MATCH(AM23,Mob_Demob!$A$6:$A$14,0)))*Settings!$B$6)+IF(AP23="Y",N(INDEX(Mob_Demob!$I$6:$I$14,MATCH(AM23,Mob_Demob!$A$6:$A$14,0)))*Settings!$B$19,0)+N(INDEX(Mob_Demob!$L$6:$L$14,MATCH(AM23,Mob_Demob!$A$6:$A$14,0)))*N(INDEX(Mob_Demob!$K$6:$K$14,MATCH(AM23,Mob_Demob!$A$6:$A$14,0)))*Settings!$B$6+N(INDEX(Mob_Demob!$M$6:$M$14,MATCH(AM23,Mob_Demob!$A$6:$A$14,0)))*N(INDEX(Mob_Demob!$N$6:$N$14,MATCH(AM23,Mob_Demob!$A$6:$A$14,0))),0)),"") -> 500 | AR23: =IF(AQ23="","",ROUND(AQ23*Settings!$B$18,0)) -> 500 | AS23: EW-CUTLOAD,EW-MASS,EW-TRENCH-5,EW-TRENCH-10,EW-STRUCT,EW-BACKFILL,UT-PIPE-STORM,DM-PAVE-CONC | AT23: Cat 308-07 CR fuel (0.95 med) is below the 305 CR (1.55) in the source; reproduced as published. Split in revision from the notes' 8-10 t class (Bobcat 7-8 / 9-10 t classes). Tail swing: zero / minimal (<10% overhang) / conventional variants exist in compact classes [BOBCAT-EX]; rental sources do not price them separately. Max dig depth: Deere 85 P 14'10"; PC88MR 15 ft [DEERE-RENT; CAT-EXC-PG]. Rent: Median of 4 sources after split (W 308 823/2388/6924; C PC88MR 650/1600/4000; B KX080/ET90 420/1260/3780; R E88 550/1995/4995). 8.4-8.8 t models assigned to the 7-8 t (nominal 8 t) class. Owned_rate_hr_incl_fuel interpolated (C) between EX-MINI-5T and EX-CRAWL-13T by Net HP (FEMA 2025 endpoints). Ex-fuel (C) = FEMA incl-fuel rate - Fuel_gal_hr_med x diesel back-out price (Settings B5). | AU23: Fuel value looks low vs smaller class
A24: EX-MIDI-10T | B24: Earthwork | C24: Hydraulic excavator | D24: Midi 9-10 t | E24: 9-10 t (~19,800-23,000 lb) | F24: Operating weight | G24: 23002 | H24: lb | I24: Cat 309 CR (21,091 lb), 310 (23,002 lb, 69.5 hp, 205.2 in dig) | J24: 23002 | K24: 69.5 | N24: diesel | O24: Operating Engineer - light/compact group (per WD) | P24: day/wk/4wk | Q24: 717 | R24: 2182 | S24: 5843 | T24: 4250 | U24: 7437 | V24: bare | Y24: W25;A26 | Z24: 2025-2026 | AA24: A | AC24: =ROUND(AC22+(AC25-AC22)*(K24-K22)/(K25-K22),2) -> 77.76 | AD24: FEMA 2025 (interpolated) | AE24: =ROUND(K24*Settings!$B$11*Settings!$B$13,2) -> 1.18 | AF24: =ROUND(K24*Settings!$B$11*Settings!$B$14,2) -> 1.55 | AG24: =ROUND(K24*Settings!$B$11*Settings!$B$15,2) -> 2.03 | AH24: Derived (C): Net_HP x 0.0486 diesel gal/bhp-hr x load factor 0.35/0.46/0.60 [USACE-EP] | AI24: =IF(OR(AC24="",AF24="",Settings!$B$5=""),"",ROUND(AC24-AF24*Settings!$B$5,2)) -> 72.09 | AJ24: C | AK24: C | AL24: Owned: USACE standby = 0.5 x DEPR + FCCM, max 40 hr/wk [USACE-EP]; with only an all-in rate use Caltrans delay factor x rate, max 8 hr/day & 40 hr/wk [CALT-2627]: HCECL factor 0.17 (book) / 0.16 (Sep 2026 interim). Rental: accrues by calendar period (no idle discount). FEMA: not eligible unless intermittent use [FEMA-PG]. | AM24: lowboy-legal | AN24: 23002 | AP24: N | AQ24: =IFERROR(IF(AND(INDEX(Mob_Demob!$D$6:$D$14,MATCH(AM24,Mob_Demob!$A$6:$A$14,0))="",INDEX(Mob_Demob!$G$6:$G$14,MATCH(AM24,Mob_Demob!$A$6:$A$14,0))=""),"",ROUND(MAX(N(INDEX(Mob_Demob!$G$6:$G$14,MATCH(AM24,Mob_Demob!$A$6:$A$14,0))),N(INDEX(Mob_Demob!$D$6:$D$14,MATCH(AM24,Mob_Demob!$A$6:$A$14,0)))*Settings!$B$6)+IF(AP24="Y",N(INDEX(Mob_Demob!$I$6:$I$14,MATCH(AM24,Mob_Demob!$A$6:$A$14,0)))*Settings!$B$19,0)+N(INDEX(Mob_Demob!$L$6:$L$14,MATCH(AM24,Mob_Demob!$A$6:$A$14,0)))*N(INDEX(Mob_Demob!$K$6:$K$14,MATCH(AM24,Mob_Demob!$A$6:$A$14,0)))*Settings!$B$6+N(INDEX(Mob_Demob!$M$6:$M$14,MATCH(AM24,Mob_Demob!$A$6:$A$14,0)))*N(INDEX(Mob_Demob!$N$6:$N$14,MATCH(AM24,Mob_Demob!$A$6:$A$14,0))),0)),"") -> 550 | AR24: =IF(AQ24="","",ROUND(AQ24*Settings!$B$18,0)) -> 550 | AS24: EW-CUTLOAD,EW-MASS,EW-TRENCH-5,EW-TRENCH-10,EW-STRUCT,EW-BACKFILL,UT-PIPE-STORM | AT24: Split from the 8-10 t class in revision. Rent: Mean of 2 sources after split (W 309/310 avg 884.5/2564/7436.5; A 18-25K lb 550/1800/4250). Ahearn 18-25K lb class straddles both midi rows; assigned here. Half-up rounding. Owned_rate_hr_incl_fuel interpolated (C) between EX-MINI-5T and EX-CRAWL-13T by Net HP (FEMA 2025 endpoints). Fuel gal/hr derived (C): Net_HP x USACE fuel factor x load factor (Settings B11-B15). Ex-fuel (C) = FEMA incl-fuel rate - Fuel_gal_hr_med x diesel back-out price (Settings B5).
