Workbook

Sheet README
A1: IntelCost Earthwork Production Starter Data (accepted as drafted, 23 Oct 2026)
A2: Starter activities, production tiers (from 200 per day upward), spreads and default production for the Earthwork production settings. Split method: Cut lines excavate and load; Fill lines place and compact.
A4: How to read it
A5: 1. Activities: the 13 activities, their unit and which Calculate line types they price (Line mapping has the full list).
A6: 2. Tiers: one row per production range with its spread. Machine and crew detail is in Tier machines and Tier crew; edit there.
A7: 3. Default production: the production per day a company normally gets, by total job quantity. This picks the tier.
A8: 4. Catalog gaps: machines in the spreads whose catalog data is incomplete, and what to enter. Rows marked "Optional (catalog gap)" are left out of the spread until filled.
A9: 5. Old sheet: what was kept from Crew_Assemley_DE_LLC V12 and what was dropped.
A10: 6. Catalog ref and Catalog production: the catalog values the other sheets look up (copied as published).
A12: Assumptions (edit on Settings; blue = input)
A13: - Production per day assumes a 10-hour work day (the old sheet's basis). Set the workspace "hours per work day" to 10, or scale the productions down for 8-hour days.
A14: - Common earth (loam): 1 BCY = 1.25 LCY = 0.90 CCY (catalog Factors sheet, FM 5-434). Place and compact defaults are kept in step with Excavate and load at 0.90.
... A23: - Nothing here changes the catalog. When approved, this file is loaded as release data for Settings > Equipment library > Earthwork production.

Sheet Settings
A1: Setting | B1: Value | C1: Note
A2: Hours per work day | B2: 10 | C2: Old sheet basis (10-hr day). Drives the capacity check only.
A3: Bank to loose (common earth) | B3: 1.25 | C3: Catalog Factors, Loam, FM 5-434
A4: Bank to compacted (common earth) | B4: 0.9 | C4: Catalog Factors, Loam, FM 5-434
A5: Tri-axle LCY per truck-day | B5: 140 | C5: Assumption: ~10 loads x 14 LCY, ~1 hr round trip. Haul tiers are sized at 140 (one tier per truck count); if you change this, change the tier ranges too. The capacity check follows this cell.

Sheet Activities
A1: ID | B1: Activity | C1: Unit | D1: Prices these Calculate lines | E1: Notes | F1: Tiers
A2: A1 | B2: Excavate and load (on-site haul) | C2: BCY | D2: cut; over-excavation; stockpile (cut to stock) | E2: Excavator loads off-road trucks that haul to the fill or stockpile on site. Pairs with A3 on the Fill lines. | F2: =COUNTIF(Tiers!$A:$A,A2) -> 9
A3: A2 | B3: Excavate and load (direct to haul-off trucks) | C3: BCY | D3: undercut (default); use for cut on export-heavy sites | E3: Excavator only: it loads the haul-off trucks priced on the Haul off line (A7). Avoids paying on-site trucks AND highway trucks for the same material. | F3: =COUNTIF(Tiers!$A:$A,A3) -> 4
A4: A3 | B4: Place and compact | C4: CCY | D4: fill; undercut_replace; undercut_native; replacement fill | E4: Dozer spreads, roller compacts. Default production kept in step with A1 (0.90 CCY per BCY, common earth). | F4: =COUNTIF(Tiers!$A:$A,A4) -> 8
A5: A4 | B5: Strip topsoil (push to stockpile) | C5: BCY | D5: strip | E5: Dozer only. Hauling the stripped topsoil away is A6 on the Haul Off line. | F5: =COUNTIF(Tiers!$A:$A,A5) -> 5
A6: A5 | B6: Respread topsoil (from stockpile) | C6: BCY | D6: strip_reuse_topsoil | E6: Load from stockpile, haul on site, spread. | F6: =COUNTIF(Tiers!$A:$A,A6) -> 4
A7: A6 | B7: Load and haul off (from stockpile) | C7: LCY | D7: strip_haul; spoils_export | E7: Loader plus hired operated tri-axles (driver and fuel in the truck rate). | F7: =COUNTIF(Tiers!$A:$A,A7) -> 11
A8: A7 | B8: Haul off (loaded by excavator) | C8: LCY | D8: soil_export; undercut_haul | E8: Hired operated tri-axles only; the excavator that loads them is on the Cut/Undercut line. | F8: =COUNTIF(Tiers!$A:$A,A8) -> 11
A9: A8 | B9: Haul in (import) | C9: LCY | D9: soil_import | E9: Hired operated tri-axles. If the material is bought delivered, map soil_import to none and price it as delivered material. | F9: =COUNTIF(Tiers!$A:$A,A9) -> 11
A10: A9 | B10: Rock excavation (break and load) | C10: BCY | D10: rock_hard_dig | E10: Excavator with hydraulic breaker. Rock starts below 200/day by nature. | F10: =COUNTIF(Tiers!$A:$A,A10) -> 4
A11: A10 | B11: Rip rock (dozer) | C11: BCY | D11: (not mapped; alternative to A9 for rippable rock) | E11: D8 class with ripper. | F11: =COUNTIF(Tiers!$A:$A,A11) -> 2
A12: A11 | B12: Fine grade / subgrade prep | C12: SF | D12: prep | E12: Grader, roller, part-time backhoe. | F12: =COUNTIF(Tiers!$A:$A,A12) -> 4
A13: A12 | B13: Pipe crew, gravity storm/sewer (excavate, lay, backfill) | C13: LF | D13: utility_pipe | E13: One crew prices the whole pipe run, so the trench excavation, backfill and bedding lines map to none (bedding stone stays a material by hand). | F13: =COUNTIF(Tiers!$A:$A,A13) -> 4
A14: A13 | B14: Trench box with pipe crew | C14: LF | D14: trench_protection | E14: Box moves with the pipe crew: give it the same production per day as A12 so the days match. | F14: =COUNTIF(Tiers!$A:$A,A14) -> 2

Sheet Tiers
A1: Activity | B1: Tier | C1: From /day | D1: To /day | E1: Unit | F1: Spread (machines) | G1: Crew | H1: Capacity check /day | I1: Check | J1: Source
A2: A1 | B2: 1 | C2: 200 | D2: 349 | E2: BCY | F2: 1 x 16-18 t (~38,000-40,000 lb) [EX-CRAWL-17T] *pacing; 1 x 26.5 t payload [ADT-25T] | G2: 0.25 Foreman; 2 Operator (auto: follows machine count) | H2: =IF(IF(COUNTIFS('Tier machines'!$G$2:$G$3,"main",'Tier machines'!$L$2:$L$3,">0")=0,9E+099,SUMIFS('Tier machines'!$L$2:$L$3,'Tier machines'!$G$2:$G$3,"main"))>=9E+099,"",IF(COUNTIFS('Tier machines'!$G$2:$G$3,"main",'Tier machines'!$L$2:$L$3,">0")=0,9E+099,SUMIFS('Tier machines'!$L$2:$L$3,'Tier machines'!$G$2:$G$3,"main"))) -> 1534.9783 | I2: =IF(H2="","No catalog figure",IF(H2>=D2,"OK",IF(H2>=C2,"Covers lower part only","Below tier"))) -> OK | J2: Draft
A3: A1 | B3: 2 | C3: 350 | D3: 599 | E3: BCY | F3: 1 x 20-25 t (~48,500-62,800 lb) [EX-CRAWL-20T] *pacing; 2 x 26.5 t payload [ADT-25T] | G3: 0.5 Foreman; 3 Operator (auto: follows machine count) | H3: =IF(IF(COUNTIFS('Tier machines'!$G$4:$G$5,"main",'Tier machines'!$L$4:$L$5,">0")=0,9E+099,SUMIFS('Tier machines'!$L$4:$L$5,'Tier machines'!$G$4:$G$5,"main"))>=9E+099,"",IF(COUNTIFS('Tier machines'!$G$4:$G$5,"main",'Tier machines'!$L$4:$L$5,">0")=0,9E+099,SUMIFS('Tier machines'!$L$4:$L$5,'Tier machines'!$G$4:$G$5,"main"))) -> 1633.44 | I3: =IF(H3="","No catalog figure",IF(H3>=D3,"OK",IF(H3>=C3,"Covers lower part only","Below tier"))) -> OK | J3: Draft
A4: A1 | B4: 3 | C4: 600 | D4: 899 | E4: BCY | F4: 1 x 20-25 t (~48,500-62,800 lb) [EX-CRAWL-20T] *pacing; 2 x 30 t payload [ADT-30T] | G4: 0.5 Foreman; 3 Operator (auto: follows machine count) | H4: =IF(IF(COUNTIFS('Tier machines'!$G$6:$G$7,"main",'Tier machines'!$L$6:$L$7,">0")=0,9E+099,SUMIFS('Tier machines'!$L$6:$L$7,'Tier machines'!$G$6:$G$7,"main"))>=9E+099,"",IF(COUNTIFS('Tier machines'!$G$6:$G$7,"main",'Tier machines'!$L$6:$L$7,">0")=0,9E+099,SUMIFS('Tier machines'!$L$6:$L$7,'Tier machines'!$G$6:$G$7,"main"))) -> 1633.44 | I4: =IF(H4="","No catalog figure",IF(H4>=D4,"OK",IF(H4>=C4,"Covers lower part only","Below tier"))) -> OK | J4: Draft
A5: A1 | B5: 4 | C5: 900 | D5: 1399 | E5: BCY | F5: 1 x 30-36 t (~68,000-81,000 lb) [EX-CRAWL-30T] *pacing; 2 x 30 t payload [ADT-30T] | G5: 0.5 Foreman; 3 Operator (auto: follows machine count); 0.5 Laborer | H5: =IF(IF(COUNTIFS('Tier machines'!$G$8:$G$9,"main",'Tier machines'!$L$8:$L$9,">0")=0,9E+099,SUMIFS('Tier machines'!$L$8:$L$9,'Tier machines'!$G$8:$G$9,"main"))>=9E+099,"",IF(COUNTIFS('Tier machines'!$G$8:$G$9,"main",'Tier machines'!$L$8:$L$9,">0")=0,9E+099,SUMIFS('Tier machines'!$L$8:$L$9,'Tier machines'!$G$8:$G$9,"main"))) -> 3107.52 | I5: =IF(H5="","No catalog figure",IF(H5>=D5,"OK",IF(H5>=C5,"Covers lower part only","Below tier"))) -> OK | J5: Old sheet: Cut to Fill 0-42,000 CY at 1,000/day (CAT 330 + 2 x 30 t ADT)
A6: A1 | B6: 5 | C6: 1400 | D6: 2199 | E6: BCY | F6: 1 x 30-36 t (~68,000-81,000 lb) [EX-CRAWL-30T] *pacing; 3 x 30 t payload [ADT-30T] | G6: 0.5 Foreman; 4 Operator (auto: follows machine count); 0.5 Laborer | H6: =IF(IF(COUNTIFS('Tier machines'!$G$10:$G$11,"main",'Tier machines'!$L$10:$L$11,">0")=0,9E+099,SUMIFS('Tier machines'!$L$10:$L$11,'Tier machines'!$G$10:$G$11,"main"))>=9E+099,"",IF(COUNTIFS('Tier machines'!$G$10:$G$11,"main",'Tier machines'!$L$10:$L$11,">0")=0,9E+099,SUMIFS('Tier machines'!$L$10:$L$11,'Tier machines'!$G$10:$G$11,"main"))) -> 3107.52 | I6: =IF(H6="","No catalog figure",IF(H6>=D6,"OK",IF(H6>=C6,"Covers lower part only","Below tier"))) -> OK | J6: Draft
A7: A1 | B7: 6 | C7: 2200 | D7: 3199 | E7: BCY | F7: 1 x 45-55 t (~105,000-108,000 lb) [EX-CRAWL-50T] *pacing; 3 x 30 t payload [ADT-30T] | G7: 0.5 Foreman; 4 Operator (auto: follows machine count); 0.5 Laborer; 0.5 Grade checker | H7: =IF(IF(COUNTIFS('Tier machines'!$G$12:$G$13,"main",'Tier machines'!$L$12:$L$13,">0")=0,9E+099,SUMIFS('Tier machines'!$L$12:$L$13,'Tier machines'!$G$12:$G$13,"main"))>=9E+099,"",IF(COUNTIFS('Tier machines'!$G$12:$G$13,"main",'Tier machines'!$L$12:$L$13,">0")=0,9E+099,SUMIFS('Tier machines'!$L$12:$L$13,'Tier machines'!$G$12:$G$13,"main"))) -> 5109.0816 | I7: =IF(H7="","No catalog figure",IF(H7>=D7,"OK",IF(H7>=C7,"Covers lower part only","Below tier"))) -> OK | J7: Old sheet: 42,000-84,000 CY at 2,275/day (CAT 345 + 2 x 40 t ADT; 40 t has no fuel in the catalog, so 3 x 30 t)
A8: A1 | B8: 7 | C8: 3200 | D8: 4499 | E8: BCY | F8: 1 x 45-55 t (~105,000-108,000 lb) [EX-CRAWL-50T] *pacing; 4 x 30 t payload [ADT-30T] | G8: 0.5 Foreman; 5 Operator (auto: follows machine count); 0.5 Laborer; 0.5 Grade checker | H8: =IF(IF(COUNTIFS('Tier machines'!$G$14:$G$15,"main",'Tier machines'!$L$14:$L$15,">0")=0,9E+099,SUMIFS('Tier machines'!$L$14:$L$15,'Tier machines'!$G$14:$G$15,"main"))>=9E+099,"",IF(COUNTIFS('Tier machines'!$G$14:$G$15,"main",'Tier machines'!$L$14:$L$15,">0")=0,9E+099,SUMIFS('Tier machines'!$L$14:$L$15,'Tier machines'!$G$14:$G$15,"main"))) -> 5109.0816 | I8: =IF(H8="","No catalog figure",IF(H8>=D8,"OK",IF(H8>=C8,"Covers lower part only","Below tier"))) -> OK | J8: Draft
A9: A1 | B9: 8 | C9: 4500 | D9: 6999 | E9: BCY | F9: 2 x 45-55 t (~105,000-108,000 lb) [EX-CRAWL-50T] *pacing; 6 x 30 t payload [ADT-30T] | G9: 0.5 Foreman; 8 Operator (auto: follows machine count); 0.5 Laborer; 0.5 Grade checker | H9: =IF(IF(COUNTIFS('Tier machines'!$G$16:$G$17,"main",'Tier machines'!$L$16:$L$17,">0")=0,9E+099,SUMIFS('Tier machines'!$L$16:$L$17,'Tier machines'!$G$16:$G$17,"main"))>=9E+099,"",IF(COUNTIFS('Tier machines'!$G$16:$G$17,"main",'Tier machines'!$L$16:$L$17,">0")=0,9E+099,SUMIFS('Tier machines'!$L$16:$L$17,'Tier machines'!$G$16:$G$17,"main"))) -> 10218.163 | I9: =IF(H9="","No catalog figure",IF(H9>=D9,"OK",IF(H9>=C9,"Covers lower part only","Below tier"))) -> OK | J9: Old sheet: 84,000-126,000 CY at 5,275/day (2 x CAT 345 + 4 x 40 t + 1 x 30 t)
A10: A1 | B10: 9 | C10: 7000 | E10: BCY | F10: 2 x 65-75 t (~145,000-163,000 lb) [EX-CRAWL-70T] *pacing; 9 x 30 t payload [ADT-30T] | G10: 1 Foreman; 11 Operator (auto: follows machine count); 1 Laborer; 1 Grade checker | H10: =IF(IF(COUNTIFS('Tier machines'!$G$18:$G$19,"main",'Tier machines'!$L$18:$L$19,">0")=0,9E+099,SUMIFS('Tier machines'!$L$18:$L$19,'Tier machines'!$G$18:$G$19,"main"))>=9E+099,"",IF(COUNTIFS('Tier machines'!$G$18:$G$19,"main",'Tier machines'!$L$18:$L$19,">0")=0,9E+099,SUMIFS('Tier machines'!$L$18:$L$19,'Tier machines'!$G$18:$G$19,"main"))) -> 15936 | I10: =IF(H10="","No catalog figure",IF(H10>=C10,"OK",IF(H10>=C10,"Covers lower part only","Below tier"))) -> OK | J10: Draft (old >126,000 CY tab was unfinished)
A11: A2 | B11: 1 | C11: 200 | D11: 599 | E11: BCY | F11: 1 x 20-25 t (~48,500-62,800 lb) [EX-CRAWL-20T] *pacing | G11: 0.25 Foreman; 1 Operator (auto: follows machine count); 0.5 Laborer (spotter) | H11: =IF(IF(COUNTIFS('Tier machines'!$G$20:$G$20,"main",'Tier machines'!$L$20:$L$20,">0")=0,9E+099,SUMIFS('Tier machines'!$L$20:$L$20,'Tier machines'!$G$20:$G$20,"main"))>=9E+099,"",IF(COUNTIFS('Tier machines'!$G$20:$G$20,"main",'Tier machines'!$L$20:$L$20,">0")=0,9E+099,SUMIFS('Tier machines'!$L$20:$L$20,'Tier machines'!$G$20:$G$20,"main"))) -> 1633.44 | I11: =IF(H11="","No catalog figure",IF(H11>=D11,"OK",IF(H11>=C11,"Covers lower part only","Below tier"))) -> OK | J11: Draft
A12: A2 | B12: 2 | C12: 600 | D12: 1399 | E12: BCY | F12: 1 x 30-36 t (~68,000-81,000 lb) [EX-CRAWL-30T] *pacing | G12: 0.25 Foreman; 1 Operator (auto: follows machine count); 0.5 Laborer (spotter) | H12: =IF(IF(COUNTIFS('Tier machines'!$G$21:$G$21,"main",'Tier machines'!$L$21:$L$21,">0")=0,9E+099,SUMIFS('Tier machines'!$L$21:$L$21,'Tier machines'!$G$21:$G$21,"main"))>=9E+099,"",IF(COUNTIFS('Tier machines'!$G$21:$G$21,"main",'Tier machines'!$L$21:$L$21,">0")=0,9E+099,SUMIFS('Tier machines'!$L$21:$L$21,'Tier machines'!$G$21:$G$21,"main"))) -> 3107.52 | I12: =IF(H12="","No catalog figure",IF(H12>=D12,"OK",IF(H12>=C12,"Covers lower part only","Below tier"))) -> OK | J12: Old sheet: Cut to Offsite 1,500/day (CAT 330)
A13: A2 | B13: 3 | C13: 1400 | D13: 2999 | E13: BCY | F13: 1 x 45-55 t (~105,000-108,000 lb) [EX-CRAWL-50T] *pacing | G13: 0.5 Foreman; 1 Operator (auto: follows machine count); 1 Laborer (spotter) | H13: =IF(IF(COUNTIFS('Tier machines'!$G$22:$G$22,"main",'Tier machines'!$L$22:$L$22,">0")=0,9E+099,SUMIFS('Tier machines'!$L$22:$L$22,'Tier machines'!$G$22:$G$22,"main"))>=9E+099,"",IF(COUNTIFS('Tier machines'!$G$22:$G$22,"main",'Tier machines'!$L$22:$L$22,">0")=0,9E+099,SUMIFS('Tier machines'!$L$22:$L$22,'Tier machines'!$G$22:$G$22,"main"))) -> 5109.0816 | I13: =IF(H13="","No catalog figure",IF(H13>=D13,"OK",IF(H13>=C13,"Covers lower part only","Below tier"))) -> OK | J13: Draft
A14: A2 | B14: 4 | C14: 3000 | E14: BCY | F14: 2 x 45-55 t (~105,000-108,000 lb) [EX-CRAWL-50T] *pacing | G14: 0.5 Foreman; 2 Operator (auto: follows machine count); 1 Laborer (spotter) | H14: =IF(IF(COUNTIFS('Tier machines'!$G$23:$G$23,"main",'Tier machines'!$L$23:$L$23,">0")=0,9E+099,SUMIFS('Tier machines'!$L$23:$L$23,'Tier machines'!$G$23:$G$23,"main"))>=9E+099,"",IF(COUNTIFS('Tier machines'!$G$23:$G$23,"main",'Tier machines'!$L$23:$L$23,">0")=0,9E+099,SUMIFS('Tier machines'!$L$23:$L$23,'Tier machines'!$G$23:$G$23,"main"))) -> 10218.163 | I14: =IF(H14="","No catalog figure",IF(H14>=C14,"OK",IF(H14>=C14,"Covers lower part only","Below tier"))) -> OK | J14: Old sheet: Export 2 x PC-400 at 2,501/day
A15: A3 | B15: 1 | C15: 200 | D15: 329 | E15: CCY | F15: 1 x D3 class (~100-104 hp, 20-24k lb) [DZ-CRAWL-D3] *pacing; 1 x 84 in smooth [CP-SD-84-SM]; 0.25 x 4,000 gal (6x4) [WT-4000] (optional, catalog gap) | G15: 0.25 Foreman; 2 Operator (auto: follows machine count) | H15: =IF(IF(COUNTIFS('Tier machines'!$G$24:$G$26,"main",'Tier machines'!$L$24:$L$26,">0")=0,9E+099,SUMIFS('Tier machines'!$L$24:$L$26,'Tier machines'!$G$24:$G$26,"main"))>=9E+099,"",IF(COUNTIFS('Tier machines'!$G$24:$G$26,"main",'Tier machines'!$L$24:$L$26,">0")=0,9E+099,SUMIFS('Tier machines'!$L$24:$L$26,'Tier machines'!$G$24:$G$26,"main"))) -> 2651.684 | I15: =IF(H15="","No catalog figure",IF(H15>=D15,"OK",IF(H15>=C15,"Covers lower part only","Below tier"))) -> OK | J15: Draft
A16: A3 | B16: 2 | C16: 330 | D16: 599 | E16: CCY | F16: 1 x D5 class (~170 hp, ~40k lb) [DZ-CRAWL-D5] *pacing; 1 x 84 in smooth [CP-SD-84-SM]; 0.5 x 4,000 gal (6x4) [WT-4000] (optional, catalog gap) | G16: 0.5 Foreman; 2 Operator (auto: follows machine count) | H16: =IF(IF(COUNTIFS('Tier machines'!$G$27:$G$29,"main",'Tier machines'!$L$27:$L$29,">0")=0,9E+099,SUMIFS('Tier machines'!$L$27:$L$29,'Tier machines'!$G$27:$G$29,"main"))>=9E+099,"",IF(COUNTIFS('Tier machines'!$G$27:$G$29,"main",'Tier machines'!$L$27:$L$29,">0")=0,9E+099,SUMIFS('Tier machines'!$L$27:$L$29,'Tier machines'!$G$27:$G$29,"main"))) -> 2651.684 | I16: =IF(H16="","No catalog figure",IF(H16>=D16,"OK",IF(H16>=C16,"Covers lower part only","Below tier"))) -> OK | J16: Draft
A17: A3 | B17: 3 | C17: 600 | D17: 849 | E17: CCY | F17: 1 x D6 class (~215-240 hp, ~50k lb) [DZ-CRAWL-D6] *pacing; 1 x 84 in smooth [CP-SD-84-SM]; 0.5 x 4,000 gal (6x4) [WT-4000] (optional, catalog gap) | G17: 0.5 Foreman; 2 Operator (auto: follows machine count); 0.5 Laborer | H17: =IF(IF(COUNTIFS('Tier machines'!$G$30:$G$32,"main",'Tier machines'!$L$30:$L$32,">0")=0,9E+099,SUMIFS('Tier machines'!$L$30:$L$32,'Tier machines'!$G$30:$G$32,"main"))>=9E+099,"",IF(COUNTIFS('Tier machines'!$G$30:$G$32,"main",'Tier machines'!$L$30:$L$32,">0")=0,9E+099,SUMIFS('Tier machines'!$L$30:$L$32,'Tier machines'!$G$30:$G$32,"main"))) -> 2651.684 | I17: =IF(H17="","No catalog figure",IF(H17>=D17,"OK",IF(H17>=C17,"Covers lower part only","Below tier"))) -> OK | J17: Draft
A18: A3 | B18: 4 | C18: 850 | D18: 1299 | E18: CCY | F18: 1 x D6 class (~215-240 hp, ~50k lb) [DZ-CRAWL-D6] *pacing; 1 x GPS/machine-control kit for dozer [AT-GPS-DOZER]; 1 x D5 class (~170 hp, ~40k lb) [DZ-CRAWL-D5]; 1 x 84 in smooth [CP-SD-84-SM]; 0.5 x 4,000 gal (6x4) [WT-4000] (optional, catalog gap) | G18: 0.5 Foreman; 3 Operator (auto: follows machine count); 0.5 Laborer | H18: =IF(IF(COUNTIFS('Tier machines'!$G$33:$G$37,"main",'Tier machines'!$L$33:$L$37,">0")=0,9E+099,SUMIFS('Tier machines'!$L$33:$L$37,'Tier machines'!$G$33:$G$37,"main"))>=9E+099,"",IF(COUNTIFS('Tier machines'!$G$33:$G$37,"main",'Tier machines'!$L$33:$L$37,">0")=0,9E+099,SUMIFS('Tier machines'!$L$33:$L$37,'Tier machines'!$G$33:$G$37,"main"))) -> 2651.684 | I18: =IF(H18="","No catalog figure",IF(H18>=D18,"OK",IF(H18>=C18,"Covers lower part only","Below tier"))) -> OK | J18: Old sheet: Cut to Fill 1,000/day placing side (D6R GPS + D5N + roller + 1/2 water truck)
A19: A3 | B19: 5 | C19: 1300 | D19: 1999 | E19: CCY | F19: 1 x D6 class (~215-240 hp, ~50k lb) [DZ-CRAWL-D6] *pacing; 1 x GPS/machine-control kit for dozer [AT-GPS-DOZER]; 1 x Cat 815 (~249 hp) [CP-TAMP-815]; 0.5 x 4,000 gal (6x4) [WT-4000] (optional, catalog gap) | G19: 0.5 Foreman; 2 Operator (auto: follows machine count); 2 Laborer | I19: Not checked | J19: Old sheet: Import Place & Compact 1,800/day (815 + D6R GPS + 1/2 water truck, 2 laborers)
A20: A3 | B20: 6 | C20: 2000 | D20: 2999 | E20: CCY | F20: 1 x D6 class (~215-240 hp, ~50k lb) [DZ-CRAWL-D6] *pacing; 1 x GPS/machine-control kit for dozer [AT-GPS-DOZER]; 2 x D5 class (~170 hp, ~40k lb) [DZ-CRAWL-D5]; 1 x Cat 815 (~249 hp) [CP-TAMP-815]; 1 x 4,000 gal (6x4) [WT-4000] (optional, catalog gap) | G20: 0.5 Foreman; 4 Operator (auto: follows machine count); 0.5 Grade checker | I20: Not checked | J20: Old sheet: 2,275/day placing side (D6R GPS + 2 x D5N + 815 + water truck)
A21: A3 | B21: 7 | C21: 3000 | D21: 5999 | E21: CCY | F21: 2 x D6 class (~215-240 hp, ~50k lb) [DZ-CRAWL-D6] *pacing; 2 x GPS/machine-control kit for dozer [AT-GPS-DOZER]; 0.5 x D8 class (~363 hp) [DZ-CRAWL-D8]; 0.5 x D5 class (~170 hp, ~40k lb) [DZ-CRAWL-D5]; 2 x Cat 815 (~249 hp) [CP-TAMP-815]; 1 x 8,000 gal ADT-based [WT-8000-ADT] (optional, catalog gap) | G21: 0.5 Foreman; 5 Operator (auto: follows machine count); 0.5 Grade checker | I21: Not checked | J21: Old sheet: 5,275/day placing side (2 x D6R GPS + 1/2 D8T + 1/2 D5N + 2 x 815 + water truck)
A22: A3 | B22: 8 | C22: 6000 | E22: CCY | F22: 2 x D8 class (~363 hp) [DZ-CRAWL-D8] *pacing; 1 x D6 class (~215-240 hp, ~50k lb) [DZ-CRAWL-D6]; 1 x GPS/machine-control kit for dozer [AT-GPS-DOZER]; 2 x Cat 825 (~405 hp) [CP-TAMP-825]; 2 x 8,000 gal ADT-based [WT-8000-ADT] (optional, catalog gap) | G22: 1 Foreman; 5 Operator (auto: follows machine count); 1 Grade checker | I22: Not checked | J22: Draft
A23: A4 | B23: 1 | C23: 200 | D23: 499 | E23: BCY | F23: 1 x D3 class (~100-104 hp, 20-24k lb) [DZ-CRAWL-D3] *pacing | G23: 0.25 Foreman; 1 Operator (auto: follows machine count) | H23: =IF(IF(COUNTIFS('Tier machines'!$G$58:$G$58,"main",'Tier machines'!$L$58:$L$58,">0")=0,9E+099,SUMIFS('Tier machines'!$L$58:$L$58,'Tier machines'!$G$58:$G$58,"main"))>=9E+099,"",IF(COUNTIFS('Tier machines'!$G$58:$G$58,"main",'Tier machines'!$L$58:$L$58,">0")=0,9E+099,SUMIFS('Tier machines'!$L$58:$L$58,'Tier machines'!$G$58:$G$58,"main"))) -> 1162.653 | I23: =IF(H23="","No catalog figure",IF(H23>=D23,"OK",IF(H23>=C23,"Covers lower part only","Below tier"))) -> OK | J23: Draft
A24: A4 | B24: 2 | C24: 500 | D24: 999 | E24: BCY | F24: 1 x D5 class (~170 hp, ~40k lb) [DZ-CRAWL-D5] *pacing | G24: 0.25 Foreman; 1 Operator (auto: follows machine count) | H24: =IF(IF(COUNTIFS('Tier machines'!$G$59:$G$59,"main",'Tier machines'!$L$59:$L$59,">0")=0,9E+099,SUMIFS('Tier machines'!$L$59:$L$59,'Tier machines'!$G$59:$G$59,"main"))>=9E+099,"",IF(COUNTIFS('Tier machines'!$G$59:$G$59,"main",'Tier machines'!$L$59:$L$59,">0")=0,9E+099,SUMIFS('Tier machines'!$L$59:$L$59,'Tier machines'!$G$59:$G$59,"main"))) -> 1870.0013 | I24: =IF(H24="","No catalog figure",IF(H24>=D24,"OK",IF(H24>=C24,"Covers lower part only","Below tier"))) -> OK | J24: Draft
A25: A4 | B25: 3 | C25: 1000 | D25: 1999 | E25: BCY | F25: 1 x D6 class (~215-240 hp, ~50k lb) [DZ-CRAWL-D6] *pacing | G25: 0.25 Foreman; 1 Operator (auto: follows machine count) | H25: =IF(IF(COUNTIFS('Tier machines'!$G$60:$G$60,"main",'Tier machines'!$L$60:$L$60,">0")=0,9E+099,SUMIFS('Tier machines'!$L$60:$L$60,'Tier machines'!$G$60:$G$60,"main"))>=9E+099,"",IF(COUNTIFS('Tier machines'!$G$60:$G$60,"main",'Tier machines'!$L$60:$L$60,">0")=0,9E+099,SUMIFS('Tier machines'!$L$60:$L$60,'Tier machines'!$G$60:$G$60,"main"))) -> 3048.9152 | I25: =IF(H25="","No catalog figure",IF(H25>=D25,"OK",IF(H25>=C25,"Covers lower part only","Below tier"))) -> OK | J25: Old sheet: Strip 1,500/day (dozer side: D6R)
A26: A4 | B26: 4 | C26: 2000 | D26: 3499 | E26: BCY | F26: 1 x D6 class (~215-240 hp, ~50k lb) [DZ-CRAWL-D6] *pacing; 1 x D5 class (~170 hp, ~40k lb) [DZ-CRAWL-D5] | G26: 0.5 Foreman; 2 Operator (auto: follows machine count) | H26: =IF(IF(COUNTIFS('Tier machines'!$G$61:$G$62,"main",'Tier machines'!$L$61:$L$62,">0")=0,9E+099,SUMIFS('Tier machines'!$L$61:$L$62,'Tier machines'!$G$61:$G$62,"main"))>=9E+099,"",IF(COUNTIFS('Tier machines'!$G$61:$G$62,"main",'Tier machines'!$L$61:$L$62,">0")=0,9E+099,SUMIFS('Tier machines'!$L$61:$L$62,'Tier machines'!$G$61:$G$62,"main"))) -> 4918.9165 | I26: =IF(H26="","No catalog figure",IF(H26>=D26,"OK",IF(H26>=C26,"Covers lower part only","Below tier"))) -> OK | J26: Old sheet: Strip with highway trucks 2,300/day (dozer side: D6M + D5N)
A27: A4 | B27: 5 | C27: 3500 | E27: BCY | F27: 1 x D8 class (~363 hp) [DZ-CRAWL-D8] *pacing; 1 x D6 class (~215-240 hp, ~50k lb) [DZ-CRAWL-D6] | G27: 0.5 Foreman; 2 Operator (auto: follows machine count) | H27: =IF(IF(COUNTIFS('Tier machines'!$G$63:$G$64,"main",'Tier machines'!$L$63:$L$64,">0")=0,9E+099,SUMIFS('Tier machines'!$L$63:$L$64,'Tier machines'!$G$63:$G$64,"main"))>=9E+099,"",IF(COUNTIFS('Tier machines'!$G$63:$G$64,"main",'Tier machines'!$L$63:$L$64,">0")=0,9E+099,SUMIFS('Tier machines'!$L$63:$L$64,'Tier machines'!$G$63:$G$64,"main"))) -> 8524.7668 | I27: =IF(H27="","No catalog figure",IF(H27>=C27,"OK",IF(H27>=C27,"Covers lower part only","Below tier"))) -> OK | J27: Draft
A28: A5 | B28: 1 | C28: 200 | D28: 499 | E28: BCY | F28: 1 x ROC >3,000 lb [CTL-LARGE] *pacing; 1 x D3 class (~100-104 hp, 20-24k lb) [DZ-CRAWL-D3] | G28: 0.25 Foreman; 2 Operator (auto: follows machine count); 1 Laborer | H28: =IF(IF(COUNTIFS('Tier machines'!$G$65:$G$66,"main",'Tier machines'!$L$65:$L$66,">0")=0,9E+099,SUMIFS('Tier machines'!$L$65:$L$66,'Tier machines'!$G$65:$G$66,"main"))>=9E+099,"",IF(COUNTIFS('Tier machines'!$G$65:$G$66,"main",'Tier machines'!$L$65:$L$66,">0")=0,9E+099,SUMIFS('Tier machines'!$L$65:$L$66,'Tier machines'!$G$65:$G$66,"main"))) -> 560.1504 | I28: =IF(H28="","No catalog figure",IF(H28>=D28,"OK",IF(H28>=C28,"Covers lower part only","Below tier"))) -> OK | J28: Draft
A29: A5 | B29: 2 | C29: 500 | D29: 999 | E29: BCY | F29: 1 x 3-3.2 yd (~170 hp) [WL-SMALL-3Y] *pacing; 1 x 26.5 t payload [ADT-25T]; 1 x D4 class (~130 hp, ~30k lb) [DZ-CRAWL-D4] | G29: 0.25 Foreman; 3 Operator (auto: follows machine count); 0.5 Laborer | H29: =IF(IF(COUNTIFS('Tier machines'!$G$67:$G$69,"main",'Tier machines'!$L$67:$L$69,">0")=0,9E+099,SUMIFS('Tier machines'!$L$67:$L$69,'Tier machines'!$G$67:$G$69,"main"))>=9E+099,"",IF(COUNTIFS('Tier machines'!$G$67:$G$69,"main",'Tier machines'!$L$67:$L$69,">0")=0,9E+099,SUMIFS('Tier machines'!$L$67:$L$69,'Tier machines'!$G$67:$G$69,"main"))) -> 2346.576 | I29: =IF(H29="","No catalog figure",IF(H29>=D29,"OK",IF(H29>=C29,"Covers lower part only","Below tier"))) -> OK | J29: Old sheet: Respread 500/day (used CAT 330 + D6M + 40 t truck; loader used here)
A30: A5 | B30: 3 | C30: 1000 | D30: 1999 | E30: BCY | F30: 1 x 4.5 yd (~225-250 hp) [WL-MED-45Y] *pacing; 2 x 30 t payload [ADT-30T]; 1 x D5 class (~170 hp, ~40k lb) [DZ-CRAWL-D5] | G30: 0.5 Foreman; 4 Operator (auto: follows machine count); 0.5 Laborer | H30: =IF(IF(COUNTIFS('Tier machines'!$G$70:$G$72,"main",'Tier machines'!$L$70:$L$72,">0")=0,9E+099,SUMIFS('Tier machines'!$L$70:$L$72,'Tier machines'!$G$70:$G$72,"main"))>=9E+099,"",IF(COUNTIFS('Tier machines'!$G$70:$G$72,"main",'Tier machines'!$L$70:$L$72,">0")=0,9E+099,SUMIFS('Tier machines'!$L$70:$L$72,'Tier machines'!$G$70:$G$72,"main"))) -> 3406.32 | I30: =IF(H30="","No catalog figure",IF(H30>=D30,"OK",IF(H30>=C30,"Covers lower part only","Below tier"))) -> OK | J30: Draft
A31: A5 | B31: 4 | C31: 2000 | E31: BCY | F31: 1 x 4.5 yd (~225-250 hp) [WL-MED-45Y] *pacing; 3 x 30 t payload [ADT-30T]; 1 x D6 class (~215-240 hp, ~50k lb) [DZ-CRAWL-D6] | G31: 0.5 Foreman; 5 Operator (auto: follows machine count); 0.5 Laborer | H31: =IF(IF(COUNTIFS('Tier machines'!$G$73:$G$75,"main",'Tier machines'!$L$73:$L$75,">0")=0,9E+099,SUMIFS('Tier machines'!$L$73:$L$75,'Tier machines'!$G$73:$G$75,"main"))>=9E+099,"",IF(COUNTIFS('Tier machines'!$G$73:$G$75,"main",'Tier machines'!$L$73:$L$75,">0")=0,9E+099,SUMIFS('Tier machines'!$L$73:$L$75,'Tier machines'!$G$73:$G$75,"main"))) -> 3406.32 | I31: =IF(H31="","No catalog figure",IF(H31>=C31,"OK",IF(H31>=C31,"Covers lower part only","Below tier"))) -> OK | J31: Draft
A32: A6 | B32: 1 | C32: 200 | D32: 280 | E32: LCY | F32: 1 x 3-3.2 yd (~170 hp) [WL-SMALL-3Y] *pacing; 2 x 3-axle (tri-axle), operated [DT-OP-3AXLE] | G32: 0.25 Foreman; 1 Operator (auto: follows machine count); 0.5 Laborer (spotter) | H32: =IF(MIN(IF(COUNTIFS('Tier machines'!$G$76:$G$77,"haul",'Tier machines'!$L$76:$L$77,">0")=0,9E+099,SUMIFS('Tier machines'!$L$76:$L$77,'Tier machines'!$G$76:$G$77,"haul")),IF(COUNTIFS('Tier machines'!$G$76:$G$77,"load",'Tier machines'!$L$76:$L$77,">0")=0,9E+099,SUMIFS('Tier machines'!$L$76:$L$77,'Tier machines'!$G$76:$G$77,"load")))>=9E+099,"",MIN(IF(COUNTIFS('Tier machines'!$G$76:$G$77,"haul",'Tier machines'!$L$76:$L$77,">0")=0,9E+099,SUMIFS('Tier machines'!$L$76:$L$77,'Tier machines'!$G$76:$G$77,"haul")),IF(COUNTIFS('Tier machines'!$G$76:$G$77,"load",'Tier machines'!$L$76:$L$77,">0")=0,9E+099,SUMIFS('Tier machines'!$L$76:$L$77,'Tier machines'!$G$76:$G$77,"load")))) -> 280 | I32: =IF(H32="","No catalog figure",IF(H32>=D32,"OK",IF(H32>=C32,"Covers lower part only","Below tier"))) -> OK | J32: Draft; 2 trucks x 140 LCY per truck-day
A33: A6 | B33: 2 | C33: 281 | D33: 420 | E33: LCY | F33: 1 x 3-3.2 yd (~170 hp) [WL-SMALL-3Y] *pacing; 3 x 3-axle (tri-axle), operated [DT-OP-3AXLE] | G33: 0.25 Foreman; 1 Operator (auto: follows machine count); 0.5 Laborer (spotter) | H33: =IF(MIN(IF(COUNTIFS('Tier machines'!$G$78:$G$79,"haul",'Tier machines'!$L$78:$L$79,">0")=0,9E+099,SUMIFS('Tier machines'!$L$78:$L$79,'Tier machines'!$G$78:$G$79,"haul")),IF(COUNTIFS('Tier machines'!$G$78:$G$79,"load",'Tier machines'!$L$78:$L$79,">0")=0,9E+099,SUMIFS('Tier machines'!$L$78:$L$79,'Tier machines'!$G$78:$G$79,"load")))>=9E+099,"",MIN(IF(COUNTIFS('Tier machines'!$G$78:$G$79,"haul",'Tier machines'!$L$78:$L$79,">0")=0,9E+099,SUMIFS('Tier machines'!$L$78:$L$79,'Tier machines'!$G$78:$G$79,"haul")),IF(COUNTIFS('Tier machines'!$G$78:$G$79,"load",'Tier machines'!$L$78:$L$79,">0")=0,9E+099,SUMIFS('Tier machines'!$L$78:$L$79,'Tier machines'!$G$78:$G$79,"load")))) -> 420 | I33: =IF(H33="","No catalog figure",IF(H33>=D33,"OK",IF(H33>=C33,"Covers lower part only","Below tier"))) -> OK | J33: Draft; 3 trucks x 140 LCY per truck-day
A34: A6 | B34: 3 | C34: 421 | D34: 560 | E34: LCY | F34: 1 x 3-3.2 yd (~170 hp) [WL-SMALL-3Y] *pacing; 4 x 3-axle (tri-axle), operated [DT-OP-3AXLE] | G34: 0.25 Foreman; 1 Operator (auto: follows machine count); 0.5 Laborer (spotter) | H34: =IF(MIN(IF(COUNTIFS('Tier machines'!$G$80:$G$81,"haul",'Tier machines'!$L$80:$L$81,">0")=0,9E+099,SUMIFS('Tier machines'!$L$80:$L$81,'Tier machines'!$G$80:$G$81,"haul")),IF(COUNTIFS('Tier machines'!$G$80:$G$81,"load",'Tier machines'!$L$80:$L$81,">0")=0,9E+099,SUMIFS('Tier machines'!$L$80:$L$81,'Tier machines'!$G$80:$G$81,"load")))>=9E+099,"",MIN(IF(COUNTIFS('Tier machines'!$G$80:$G$81,"haul",'Tier machines'!$L$80:$L$81,">0")=0,9E+099,SUMIFS('Tier machines'!$L$80:$L$81,'Tier machines'!$G$80:$G$81,"haul")),IF(COUNTIFS('Tier machines'!$G$80:$G$81,"load",'Tier machines'!$L$80:$L$81,">0")=0,9E+099,SUMIFS('Tier machines'!$L$80:$L$81,'Tier machines'!$G$80:$G$81,"load")))) -> 560 | I34: =IF(H34="","No catalog figure",IF(H34>=D34,"OK",IF(H34>=C34,"Covers lower part only","Below tier"))) -> OK | J34: Draft; 4 trucks x 140 LCY per truck-day
A35: A6 | B35: 4 | C35: 561 | D35: 700 | E35: LCY | F35: 1 x 3-3.2 yd (~170 hp) [WL-SMALL-3Y] *pacing; 5 x 3-axle (tri-axle), operated [DT-OP-3AXLE] | G35: 0.25 Foreman; 1 Operator (auto: follows machine count); 0.5 Laborer (spotter) | H35: =IF(MIN(IF(COUNTIFS('Tier machines'!$G$82:$G$83,"haul",'Tier machines'!$L$82:$L$83,">0")=0,9E+099,SUMIFS('Tier machines'!$L$82:$L$83,'Tier machines'!$G$82:$G$83,"haul")),IF(COUNTIFS('Tier machines'!$G$82:$G$83,"load",'Tier machines'!$L$82:$L$83,">0")=0,9E+099,SUMIFS('Tier machines'!$L$82:$L$83,'Tier machines'!$G$82:$G$83,"load")))>=9E+099,"",MIN(IF(COUNTIFS('Tier machines'!$G$82:$G$83,"haul",'Tier machines'!$L$82:$L$83,">0")=0,9E+099,SUMIFS('Tier machines'!$L$82:$L$83,'Tier machines'!$G$82:$G$83,"haul")),IF(COUNTIFS('Tier machines'!$G$82:$G$83,"load",'Tier machines'!$L$82:$L$83,">0")=0,9E+099,SUMIFS('Tier machines'!$L$82:$L$83,'Tier machines'!$G$82:$G$83,"load")))) -> 700 | I35: =IF(H35="","No catalog figure",IF(H35>=D35,"OK",IF(H35>=C35,"Covers lower part only","Below tier"))) -> OK | J35: Draft; 5 trucks x 140 LCY per truck-day
A36: A6 | B36: 5 | C36: 701 | D36: 840 | E36: LCY | F36: 1 x 3-3.2 yd (~170 hp) [WL-SMALL-3Y] *pacing; 6 x 3-axle (tri-axle), operated [DT-OP-3AXLE] | G36: 0.25 Foreman; 1 Operator (auto: follows machine count); 0.5 Laborer (spotter) | H36: =IF(MIN(IF(COUNTIFS('Tier machines'!$G$84:$G$85,"haul",'Tier machines'!$L$84:$L$85,">0")=0,9E+099,SUMIFS('Tier machines'!$L$84:$L$85,'Tier machines'!$G$84:$G$85,"haul")),IF(COUNTIFS('Tier machines'!$G$84:$G$85,"load",'Tier machines'!$L$84:$L$85,">0")=0,9E+099,SUMIFS('Tier machines'!$L$84:$L$85,'Tier machines'!$G$84:$G$85,"load")))>=9E+099,"",MIN(IF(COUNTIFS('Tier machines'!$G$84:$G$85,"haul",'Tier machines'!$L$84:$L$85,">0")=0,9E+099,SUMIFS('Tier machines'!$L$84:$L$85,'Tier machines'!$G$84:$G$85,"haul")),IF(COUNTIFS('Tier machines'!$G$84:$G$85,"load",'Tier machines'!$L$84:$L$85,">0")=0,9E+099,SUMIFS('Tier machines'!$L$84:$L$85,'Tier machines'!$G$84:$G$85,"load")))) -> 840 | I36: =IF(H36="","No catalog figure",IF(H36>=D36,"OK",IF(H36>=C36,"Covers lower part only","Below tier"))) -> OK | J36: Draft; 6 trucks x 140 LCY per truck-day
A37: A6 | B37: 6 | C37: 841 | D37: 1120 | E37: LCY | F37: 1 x 3-3.2 yd (~170 hp) [WL-SMALL-3Y] *pacing; 8 x 3-axle (tri-axle), operated [DT-OP-3AXLE] | G37: 0.25 Foreman; 1 Operator (auto: follows machine count); 0.5 Laborer (spotter) | H37: =IF(MIN(IF(COUNTIFS('Tier machines'!$G$86:$G$87,"haul",'Tier machines'!$L$86:$L$87,">0")=0,9E+099,SUMIFS('Tier machines'!$L$86:$L$87,'Tier machines'!$G$86:$G$87,"haul")),IF(COUNTIFS('Tier machines'!$G$86:$G$87,"load",'Tier machines'!$L$86:$L$87,">0")=0,9E+099,SUMIFS('Tier machines'!$L$86:$L$87,'Tier machines'!$G$86:$G$87,"load")))>=9E+099,"",MIN(IF(COUNTIFS('Tier machines'!$G$86:$G$87,"haul",'Tier machines'!$L$86:$L$87,">0")=0,9E+099,SUMIFS('Tier machines'!$L$86:$L$87,'Tier machines'!$G$86:$G$87,"haul")),IF(COUNTIFS('Tier machines'!$G$86:$G$87,"load",'Tier machines'!$L$86:$L$87,">0")=0,9E+099,SUMIFS('Tier machines'!$L$86:$L$87,'Tier machines'!$G$86:$G$87,"load")))) -> 1120 | I37: =IF(H37="","No catalog figure",IF(H37>=D37,"OK",IF(H37>=C37,"Covers lower part only","Below tier"))) -> OK | J37: Draft; 8 trucks x 140 LCY per truck-day
A38: A6 | B38: 7 | C38: 1121 | D38: 1400 | E38: LCY | F38: 1 x 4.5 yd (~225-250 hp) [WL-MED-45Y] *pacing; 10 x 3-axle (tri-axle), operated [DT-OP-3AXLE] | G38: 0.5 Foreman; 1 Operator (auto: follows machine count); 0.5 Laborer (spotter) | H38: =IF(MIN(IF(COUNTIFS('Tier machines'!$G$88:$G$89,"haul",'Tier machines'!$L$88:$L$89,">0")=0,9E+099,SUMIFS('Tier machines'!$L$88:$L$89,'Tier machines'!$G$88:$G$89,"haul")),IF(COUNTIFS('Tier machines'!$G$88:$G$89,"load",'Tier machines'!$L$88:$L$89,">0")=0,9E+099,SUMIFS('Tier machines'!$L$88:$L$89,'Tier machines'!$G$88:$G$89,"load")))>=9E+099,"",MIN(IF(COUNTIFS('Tier machines'!$G$88:$G$89,"haul",'Tier machines'!$L$88:$L$89,">0")=0,9E+099,SUMIFS('Tier machines'!$L$88:$L$89,'Tier machines'!$G$88:$G$89,"haul")),IF(COUNTIFS('Tier machines'!$G$88:$G$89,"load",'Tier machines'!$L$88:$L$89,">0")=0,9E+099,SUMIFS('Tier machines'!$L$88:$L$89,'Tier machines'!$G$88:$G$89,"load")))) -> 1400 | I38: =IF(H38="","No catalog figure",IF(H38>=D38,"OK",IF(H38>=C38,"Covers lower part only","Below tier"))) -> OK | J38: Draft; 10 trucks x 140 LCY per truck-day
A39: A6 | B39: 8 | C39: 1401 | D39: 1680 | E39: LCY | F39: 1 x 4.5 yd (~225-250 hp) [WL-MED-45Y] *pacing; 12 x 3-axle (tri-axle), operated [DT-OP-3AXLE] | G39: 0.5 Foreman; 1 Operator (auto: follows machine count); 0.5 Laborer (spotter) | H39: =IF(MIN(IF(COUNTIFS('Tier machines'!$G$90:$G$91,"haul",'Tier machines'!$L$90:$L$91,">0")=0,9E+099,SUMIFS('Tier machines'!$L$90:$L$91,'Tier machines'!$G$90:$G$91,"haul")),IF(COUNTIFS('Tier machines'!$G$90:$G$91,"load",'Tier machines'!$L$90:$L$91,">0")=0,9E+099,SUMIFS('Tier machines'!$L$90:$L$91,'Tier machines'!$G$90:$G$91,"load")))>=9E+099,"",MIN(IF(COUNTIFS('Tier machines'!$G$90:$G$91,"haul",'Tier machines'!$L$90:$L$91,">0")=0,9E+099,SUMIFS('Tier machines'!$L$90:$L$91,'Tier machines'!$G$90:$G$91,"haul")),IF(COUNTIFS('Tier machines'!$G$90:$G$91,"load",'Tier machines'!$L$90:$L$91,">0")=0,9E+099,SUMIFS('Tier machines'!$L$90:$L$91,'Tier machines'!$G$90:$G$91,"load")))) -> 1680 | I39: =IF(H39="","No catalog figure",IF(H39>=D39,"OK",IF(H39>=C39,"Covers lower part only","Below tier"))) -> OK | J39: Draft; 12 trucks x 140 LCY per truck-day
A40: A6 | B40: 9 | C40: 1681 | D40: 2100 | E40: LCY | F40: 1 x 4.5 yd (~225-250 hp) [WL-MED-45Y] *pacing; 15 x 3-axle (tri-axle), operated [DT-OP-3AXLE] | G40: 0.5 Foreman; 1 Operator (auto: follows machine count); 0.5 Laborer (spotter) | H40: =IF(MIN(IF(COUNTIFS('Tier machines'!$G$92:$G$93,"haul",'Tier machines'!$L$92:$L$93,">0")=0,9E+099,SUMIFS('Tier machines'!$L$92:$L$93,'Tier machines'!$G$92:$G$93,"haul")),IF(COUNTIFS('Tier machines'!$G$92:$G$93,"load",'Tier machines'!$L$92:$L$93,">0")=0,9E+099,SUMIFS('Tier machines'!$L$92:$L$93,'Tier machines'!$G$92:$G$93,"load")))>=9E+099,"",MIN(IF(COUNTIFS('Tier machines'!$G$92:$G$93,"haul",'Tier machines'!$L$92:$L$93,">0")=0,9E+099,SUMIFS('Tier machines'!$L$92:$L$93,'Tier machines'!$G$92:$G$93,"haul")),IF(COUNTIFS('Tier machines'!$G$92:$G$93,"load",'Tier machines'!$L$92:$L$93,">0")=0,9E+099,SUMIFS('Tier machines'!$L$92:$L$93,'Tier machines'!$G$92:$G$93,"load")))) -> 2100 | I40: =IF(H40="","No catalog figure",IF(H40>=D40,"OK",IF(H40>=C40,"Covers lower part only","Below tier"))) -> OK | J40: Draft; 15 trucks x 140 LCY per truck-day
...

Sheet Default production
A1: Activity | B1: Activity name | C1: Job quantity from | D1: Job quantity to | E1: Unit | F1: Default production /day | G1: Tier it lands in
A2: A1 | B2: Excavate and load (on-site haul) | C2: 0 | D2: 999 | E2: BCY | F2: 250 | G2: =SUMPRODUCT((Tiers!$A$2:$A$200=A2)*(Tiers!$C$2:$C$200<=F2)*((Tiers!$D$2:$D$200="")+(Tiers!$D$2:$D$200>=F2)>0)*Tiers!$B$2:$B$200) -> 1
A3: A1 | B3: Excavate and load (on-site haul) | C3: 1000 | D3: 2999 | E3: BCY | F3: 400 | G3: =SUMPRODUCT((Tiers!$A$2:$A$200=A3)*(Tiers!$C$2:$C$200<=F3)*((Tiers!$D$2:$D$200="")+(Tiers!$D$2:$D$200>=F3)>0)*Tiers!$B$2:$B$200) -> 2
A4: A1 | B4: Excavate and load (on-site haul) | C4: 3000 | D4: 7999 | E4: BCY | F4: 700 | G4: =SUMPRODUCT((Tiers!$A$2:$A$200=A4)*(Tiers!$C$2:$C$200<=F4)*((Tiers!$D$2:$D$200="")+(Tiers!$D$2:$D$200>=F4)>0)*Tiers!$B$2:$B$200) -> 3
A5: A1 | B5: Excavate and load (on-site haul) | C5: 8000 | D5: 19999 | E5: BCY | F5: 1000 | G5: =SUMPRODUCT((Tiers!$A$2:$A$200=A5)*(Tiers!$C$2:$C$200<=F5)*((Tiers!$D$2:$D$200="")+(Tiers!$D$2:$D$200>=F5)>0)*Tiers!$B$2:$B$200) -> 4
A6: A1 | B6: Excavate and load (on-site haul) | C6: 20000 | D6: 41999 | E6: BCY | F6: 1500 | G6: =SUMPRODUCT((Tiers!$A$2:$A$200=A6)*(Tiers!$C$2:$C$200<=F6)*((Tiers!$D$2:$D$200="")+(Tiers!$D$2:$D$200>=F6)>0)*Tiers!$B$2:$B$200) -> 5
A7: A1 | B7: Excavate and load (on-site haul) | C7: 42000 | D7: 83999 | E7: BCY | F7: 2500 | G7: =SUMPRODUCT((Tiers!$A$2:$A$200=A7)*(Tiers!$C$2:$C$200<=F7)*((Tiers!$D$2:$D$200="")+(Tiers!$D$2:$D$200>=F7)>0)*Tiers!$B$2:$B$200) -> 6
A8: A1 | B8: Excavate and load (on-site haul) | C8: 84000 | D8: 125999 | E8: BCY | F8: 5000 | G8: =SUMPRODUCT((Tiers!$A$2:$A$200=A8)*(Tiers!$C$2:$C$200<=F8)*((Tiers!$D$2:$D$200="")+(Tiers!$D$2:$D$200>=F8)>0)*Tiers!$B$2:$B$200) -> 8
A9: A1 | B9: Excavate and load (on-site haul) | C9: 126000 | E9: BCY | F9: 8000 | G9: =SUMPRODUCT((Tiers!$A$2:$A$200=A9)*(Tiers!$C$2:$C$200<=F9)*((Tiers!$D$2:$D$200="")+(Tiers!$D$2:$D$200>=F9)>0)*Tiers!$B$2:$B$200) -> 9
A10: A2 | B10: Excavate and load (direct to haul-off trucks) | C10: 0 | D10: 999 | E10: BCY | F10: 250 | G10: =SUMPRODUCT((Tiers!$A$2:$A$200=A10)*(Tiers!$C$2:$C$200<=F10)*((Tiers!$D$2:$D$200="")+(Tiers!$D$2:$D$200>=F10)>0)*Tiers!$B$2:$B$200) -> 1
A11: A2 | B11: Excavate and load (direct to haul-off trucks) | C11: 1000 | D11: 2999 | E11: BCY | F11: 400 | G11: =SUMPRODUCT((Tiers!$A$2:$A$200=A11)*(Tiers!$C$2:$C$200<=F11)*((Tiers!$D$2:$D$200="")+(Tiers!$D$2:$D$200>=F11)>0)*Tiers!$B$2:$B$200) -> 1
A12: A2 | B12: Excavate and load (direct to haul-off trucks) | C12: 3000 | D12: 7999 | E12: BCY | F12: 700 | G12: =SUMPRODUCT((Tiers!$A$2:$A$200=A12)*(Tiers!$C$2:$C$200<=F12)*((Tiers!$D$2:$D$200="")+(Tiers!$D$2:$D$200>=F12)>0)*Tiers!$B$2:$B$200) -> 2
A13: A2 | B13: Excavate and load (direct to haul-off trucks) | C13: 8000 | D13: 19999 | E13: BCY | F13: 1000 | G13: =SUMPRODUCT((Tiers!$A$2:$A$200=A13)*(Tiers!$C$2:$C$200<=F13)*((Tiers!$D$2:$D$200="")+(Tiers!$D$2:$D$200>=F13)>0)*Tiers!$B$2:$B$200) -> 2
A14: A2 | B14: Excavate and load (direct to haul-off trucks) | C14: 20000 | D14: 41999 | E14: BCY | F14: 1500 | G14: =SUMPRODUCT((Tiers!$A$2:$A$200=A14)*(Tiers!$C$2:$C$200<=F14)*((Tiers!$D$2:$D$200="")+(Tiers!$D$2:$D$200>=F14)>0)*Tiers!$B$2:$B$200) -> 3
A15: A2 | B15: Excavate and load (direct to haul-off trucks) | C15: 42000 | D15: 83999 | E15: BCY | F15: 2500 | G15: =SUMPRODUCT((Tiers!$A$2:$A$200=A15)*(Tiers!$C$2:$C$200<=F15)*((Tiers!$D$2:$D$200="")+(Tiers!$D$2:$D$200>=F15)>0)*Tiers!$B$2:$B$200) -> 3
A16: A2 | B16: Excavate and load (direct to haul-off trucks) | C16: 84000 | E16: BCY | F16: 4000 | G16: =SUMPRODUCT((Tiers!$A$2:$A$200=A16)*(Tiers!$C$2:$C$200<=F16)*((Tiers!$D$2:$D$200="")+(Tiers!$D$2:$D$200>=F16)>0)*Tiers!$B$2:$B$200) -> 4
A17: A3 | B17: Place and compact | C17: 0 | D17: 899 | E17: CCY | F17: 225 | G17: =SUMPRODUCT((Tiers!$A$2:$A$200=A17)*(Tiers!$C$2:$C$200<=F17)*((Tiers!$D$2:$D$200="")+(Tiers!$D$2:$D$200>=F17)>0)*Tiers!$B$2:$B$200) -> 1
A18: A3 | B18: Place and compact | C18: 900 | D18: 2699 | E18: CCY | F18: 360 | G18: =SUMPRODUCT((Tiers!$A$2:$A$200=A18)*(Tiers!$C$2:$C$200<=F18)*((Tiers!$D$2:$D$200="")+(Tiers!$D$2:$D$200>=F18)>0)*Tiers!$B$2:$B$200) -> 2
A19: A3 | B19: Place and compact | C19: 2700 | D19: 7199 | E19: CCY | F19: 630 | G19: =SUMPRODUCT((Tiers!$A$2:$A$200=A19)*(Tiers!$C$2:$C$200<=F19)*((Tiers!$D$2:$D$200="")+(Tiers!$D$2:$D$200>=F19)>0)*Tiers!$B$2:$B$200) -> 3
A20: A3 | B20: Place and compact | C20: 7200 | D20: 17999 | E20: CCY | F20: 900 | G20: =SUMPRODUCT((Tiers!$A$2:$A$200=A20)*(Tiers!$C$2:$C$200<=F20)*((Tiers!$D$2:$D$200="")+(Tiers!$D$2:$D$200>=F20)>0)*Tiers!$B$2:$B$200) -> 4
A21: A3 | B21: Place and compact | C21: 18000 | D21: 37799 | E21: CCY | F21: 1350 | G21: =SUMPRODUCT((Tiers!$A$2:$A$200=A21)*(Tiers!$C$2:$C$200<=F21)*((Tiers!$D$2:$D$200="")+(Tiers!$D$2:$D$200>=F21)>0)*Tiers!$B$2:$B$200) -> 5
A22: A3 | B22: Place and compact | C22: 37800 | D22: 75599 | E22: CCY | F22: 2250 | G22: =SUMPRODUCT((Tiers!$A$2:$A$200=A22)*(Tiers!$C$2:$C$200<=F22)*((Tiers!$D$2:$D$200="")+(Tiers!$D$2:$D$200>=F22)>0)*Tiers!$B$2:$B$200) -> 6
A23: A3 | B23: Place and compact | C23: 75600 | D23: 113399 | E23: CCY | F23: 4500 | G23: =SUMPRODUCT((Tiers!$A$2:$A$200=A23)*(Tiers!$C$2:$C$200<=F23)*((Tiers!$D$2:$D$200="")+(Tiers!$D$2:$D$200>=F23)>0)*Tiers!$B$2:$B$200) -> 7
A24: A3 | B24: Place and compact | C24: 113400 | E24: CCY | F24: 7200 | G24: =SUMPRODUCT((Tiers!$A$2:$A$200=A24)*(Tiers!$C$2:$C$200<=F24)*((Tiers!$D$2:$D$200="")+(Tiers!$D$2:$D$200>=F24)>0)*Tiers!$B$2:$B$200) -> 8
A25: A4 | B25: Strip topsoil (push to stockpile) | C25: 0 | D25: 999 | E25: BCY | F25: 300 | G25: =SUMPRODUCT((Tiers!$A$2:$A$200=A25)*(Tiers!$C$2:$C$200<=F25)*((Tiers!$D$2:$D$200="")+(Tiers!$D$2:$D$200>=F25)>0)*Tiers!$B$2:$B$200) -> 1
A26: A4 | B26: Strip topsoil (push to stockpile) | C26: 1000 | D26: 4999 | E26: BCY | F26: 700 | G26: =SUMPRODUCT((Tiers!$A$2:$A$200=A26)*(Tiers!$C$2:$C$200<=F26)*((Tiers!$D$2:$D$200="")+(Tiers!$D$2:$D$200>=F26)>0)*Tiers!$B$2:$B$200) -> 2
A27: A4 | B27: Strip topsoil (push to stockpile) | C27: 5000 | D27: 14999 | E27: BCY | F27: 1500 | G27: =SUMPRODUCT((Tiers!$A$2:$A$200=A27)*(Tiers!$C$2:$C$200<=F27)*((Tiers!$D$2:$D$200="")+(Tiers!$D$2:$D$200>=F27)>0)*Tiers!$B$2:$B$200) -> 3
A28: A4 | B28: Strip topsoil (push to stockpile) | C28: 15000 | E28: BCY | F28: 2300 | G28: =SUMPRODUCT((Tiers!$A$2:$A$200=A28)*(Tiers!$C$2:$C$200<=F28)*((Tiers!$D$2:$D$200="")+(Tiers!$D$2:$D$200>=F28)>0)*Tiers!$B$2:$B$200) -> 4
A29: A5 | B29: Respread topsoil (from stockpile) | C29: 0 | D29: 999 | E29: BCY | F29: 300 | G29: =SUMPRODUCT((Tiers!$A$2:$A$200=A29)*(Tiers!$C$2:$C$200<=F29)*((Tiers!$D$2:$D$200="")+(Tiers!$D$2:$D$200>=F29)>0)*Tiers!$B$2:$B$200) -> 1
A30: A5 | B30: Respread topsoil (from stockpile) | C30: 1000 | D30: 4999 | E30: BCY | F30: 600 | G30: =SUMPRODUCT((Tiers!$A$2:$A$200=A30)*(Tiers!$C$2:$C$200<=F30)*((Tiers!$D$2:$D$200="")+(Tiers!$D$2:$D$200>=F30)>0)*Tiers!$B$2:$B$200) -> 2
A31: A5 | B31: Respread topsoil (from stockpile) | C31: 5000 | D31: 14999 | E31: BCY | F31: 1200 | G31: =SUMPRODUCT((Tiers!$A$2:$A$200=A31)*(Tiers!$C$2:$C$200<=F31)*((Tiers!$D$2:$D$200="")+(Tiers!$D$2:$D$200>=F31)>0)*Tiers!$B$2:$B$200) -> 3
A32: A5 | B32: Respread topsoil (from stockpile) | C32: 15000 | E32: BCY | F32: 2000 | G32: =SUMPRODUCT((Tiers!$A$2:$A$200=A32)*(Tiers!$C$2:$C$200<=F32)*((Tiers!$D$2:$D$200="")+(Tiers!$D$2:$D$200>=F32)>0)*Tiers!$B$2:$B$200) -> 4
A33: A6 | B33: Load and haul off (from stockpile) | C33: 0 | D33: 499 | E33: LCY | F33: 250 | G33: =SUMPRODUCT((Tiers!$A$2:$A$200=A33)*(Tiers!$C$2:$C$200<=F33)*((Tiers!$D$2:$D$200="")+(Tiers!$D$2:$D$200>=F33)>0)*Tiers!$B$2:$B$200) -> 1
A34: A6 | B34: Load and haul off (from stockpile) | C34: 500 | D34: 2999 | E34: LCY | F34: 420 | G34: =SUMPRODUCT((Tiers!$A$2:$A$200=A34)*(Tiers!$C$2:$C$200<=F34)*((Tiers!$D$2:$D$200="")+(Tiers!$D$2:$D$200>=F34)>0)*Tiers!$B$2:$B$200) -> 2
A35: A6 | B35: Load and haul off (from stockpile) | C35: 3000 | D35: 9999 | E35: LCY | F35: 700 | G35: =SUMPRODUCT((Tiers!$A$2:$A$200=A35)*(Tiers!$C$2:$C$200<=F35)*((Tiers!$D$2:$D$200="")+(Tiers!$D$2:$D$200>=F35)>0)*Tiers!$B$2:$B$200) -> 4
A36: A6 | B36: Load and haul off (from stockpile) | C36: 10000 | D36: 29999 | E36: LCY | F36: 1120 | G36: =SUMPRODUCT((Tiers!$A$2:$A$200=A36)*(Tiers!$C$2:$C$200<=F36)*((Tiers!$D$2:$D$200="")+(Tiers!$D$2:$D$200>=F36)>0)*Tiers!$B$2:$B$200) -> 6
A37: A6 | B37: Load and haul off (from stockpile) | C37: 30000 | D37: 59999 | E37: LCY | F37: 1680 | G37: =SUMPRODUCT((Tiers!$A$2:$A$200=A37)*(Tiers!$C$2:$C$200<=F37)*((Tiers!$D$2:$D$200="")+(Tiers!$D$2:$D$200>=F37)>0)*Tiers!$B$2:$B$200) -> 8
A38: A6 | B38: Load and haul off (from stockpile) | C38: 60000 | E38: LCY | F38: 2520 | G38: =SUMPRODUCT((Tiers!$A$2:$A$200=A38)*(Tiers!$C$2:$C$200<=F38)*((Tiers!$D$2:$D$200="")+(Tiers!$D$2:$D$200>=F38)>0)*Tiers!$B$2:$B$200) -> 10
A39: A7 | B39: Haul off (loaded by excavator) | C39: 0 | D39: 499 | E39: LCY | F39: 250 | G39: =SUMPRODUCT((Tiers!$A$2:$A$200=A39)*(Tiers!$C$2:$C$200<=F39)*((Tiers!$D$2:$D$200="")+(Tiers!$D$2:$D$200>=F39)>0)*Tiers!$B$2:$B$200) -> 1
A40: A7 | B40: Haul off (loaded by excavator) | C40: 500 | D40: 2999 | E40: LCY | F40: 420 | G40: =SUMPRODUCT((Tiers!$A$2:$A$200=A40)*(Tiers!$C$2:$C$200<=F40)*((Tiers!$D$2:$D$200="")+(Tiers!$D$2:$D$200>=F40)>0)*Tiers!$B$2:$B$200) -> 2
...

Sheet Line mapping
A1: Calculate line type (code key) | B1: Unit | C1: Activity | D1: Activity name | E1: Note
A2: cut | B2: BCY | C2: A1 | D2: =IF(C2="none","(not priced automatically)",IFERROR(INDEX(Activities!$B$2:$B$14,MATCH(C2,Activities!$A$2:$A$14,0)),"?")) -> Excavate and load (on-site haul) | E2: Calculate (confirmed overnight)
A3: fill | B3: CCY | C3: A3 | D3: =IF(C3="none","(not priced automatically)",IFERROR(INDEX(Activities!$B$2:$B$14,MATCH(C3,Activities!$A$2:$A$14,0)),"?")) -> Place and compact | E3: Calculate (confirmed)
A4: strip | B4: BCY | C4: A4 | D4: =IF(C4="none","(not priced automatically)",IFERROR(INDEX(Activities!$B$2:$B$14,MATCH(C4,Activities!$A$2:$A$14,0)),"?")) -> Strip topsoil (push to stockpile) | E4: Calculate (confirmed)
A5: strip_haul | B5: LCY | C5: A6 | D5: =IF(C5="none","(not priced automatically)",IFERROR(INDEX(Activities!$B$2:$B$14,MATCH(C5,Activities!$A$2:$A$14,0)),"?")) -> Load and haul off (from stockpile) | E5: Calculate (confirmed)
A6: strip_reuse_topsoil | B6: BCY | C6: A5 | D6: =IF(C6="none","(not priced automatically)",IFERROR(INDEX(Activities!$B$2:$B$14,MATCH(C6,Activities!$A$2:$A$14,0)),"?")) -> Respread topsoil (from stockpile) | E6: Calculate (confirmed; BCY, not LCY)
A7: undercut | B7: BCY | C7: A2 | D7: =IF(C7="none","(not priced automatically)",IFERROR(INDEX(Activities!$B$2:$B$14,MATCH(C7,Activities!$A$2:$A$14,0)),"?")) -> Excavate and load (direct to haul-off trucks) | E7: Calculate (confirmed)
A8: undercut_haul | B8: LCY | C8: A7 | D8: =IF(C8="none","(not priced automatically)",IFERROR(INDEX(Activities!$B$2:$B$14,MATCH(C8,Activities!$A$2:$A$14,0)),"?")) -> Haul off (loaded by excavator) | E8: Calculate (confirmed)
A9: undercut_native | B9: CY | C9: A3 | D9: =IF(C9="none","(not priced automatically)",IFERROR(INDEX(Activities!$B$2:$B$14,MATCH(C9,Activities!$A$2:$A$14,0)),"?")) -> Place and compact | E9: Calculate (confirmed)
A10: undercut_replace | B10: CCY | C10: A3 | D10: =IF(C10="none","(not priced automatically)",IFERROR(INDEX(Activities!$B$2:$B$14,MATCH(C10,Activities!$A$2:$A$14,0)),"?")) -> Place and compact | E10: Calculate (confirmed)
A11: soil_export | B11: LCY | C11: A7 | D11: =IF(C11="none","(not priced automatically)",IFERROR(INDEX(Activities!$B$2:$B$14,MATCH(C11,Activities!$A$2:$A$14,0)),"?")) -> Haul off (loaded by excavator) | E11: Calculate (confirmed)
A12: soil_import | B12: LCY | C12: A8 | D12: =IF(C12="none","(not priced automatically)",IFERROR(INDEX(Activities!$B$2:$B$14,MATCH(C12,Activities!$A$2:$A$14,0)),"?")) -> Haul in (import) | E12: Calculate (confirmed)
A13: spoils_export | B13: LCY | C13: A6 | D13: =IF(C13="none","(not priced automatically)",IFERROR(INDEX(Activities!$B$2:$B$14,MATCH(C13,Activities!$A$2:$A$14,0)),"?")) -> Load and haul off (from stockpile) | E13: Calculate (confirmed)
... A27: geosynthetics | B27: SY | C27: none | D27: =IF(C27="none","(not priced automatically)",IFERROR(INDEX(Activities!$B$2:$B$14,MATCH(C27,Activities!$A$2:$A$14,0)),"?")) -> (not priced automatically) | E27: Material and labour by hand; key name to confirm
A29: Export-heavy site: switch "cut" to A2 so the cut is not paid with on-site trucks and haul-off trucks.

Sheet Tier machines
A1: Activity | B1: Tier | C1: Equip_ID | D1: Size class | E1: Count | F1: Pacing | G1: Capacity group | H1: Optional (catalog gap) | I1: Capacity activity | J1: Catalog production /hr | K1: Unit | L1: Capacity per day (activity unit) | M1: Rent day | N1: Fuel gal/hr med | O1: Mob one way @50 mi
A2: A1 | B2: 1 | C2: EX-CRAWL-17T | D2: =INDEX('Catalog ref'!$C$2:$C$33,MATCH(C2,'Catalog ref'!$A$2:$A$33,0)) -> 16-18 t (~38,000-40,000 lb) | E2: 1 | F2: Y | G2: main | I2: EW-CUTLOAD | J2: =IFERROR(INDEX('Catalog production'!$D$2:$D$15,MATCH(C2&"|"&I2,'Catalog production'!$A$2:$A$15,0))*1,"") -> 153.49783 | K2: =IFERROR(INDEX('Catalog production'!$E$2:$E$15,MATCH(C2&"|"&I2,'Catalog production'!$A$2:$A$15,0))&"","") -> BCY/hr | L2: =IF(N(J2)=0,"",E2*J2*Settings!$B$2*IF(K2="LCY/hr",1/Settings!$B$3,1)) -> 1534.9783 | M2: =INDEX('Catalog ref'!$D$2:$D$33,MATCH(C2,'Catalog ref'!$A$2:$A$33,0)) -> 855 | N2: =INDEX('Catalog ref'!$K$2:$K$33,MATCH(C2,'Catalog ref'!$A$2:$A$33,0)) -> 2.97 | O2: =INDEX('Catalog ref'!$M$2:$M$33,MATCH(C2,'Catalog ref'!$A$2:$A$33,0)) -> 550
A3: A1 | B3: 1 | C3: ADT-25T | D3: =INDEX('Catalog ref'!$C$2:$C$33,MATCH(C3,'Catalog ref'!$A$2:$A$33,0)) -> 26.5 t payload | E3: 1 | M3: =INDEX('Catalog ref'!$D$2:$D$33,MATCH(C3,'Catalog ref'!$A$2:$A$33,0)) -> 1882 | N3: =INDEX('Catalog ref'!$K$2:$K$33,MATCH(C3,'Catalog ref'!$A$2:$A$33,0)) -> 4.56 | O3: =INDEX('Catalog ref'!$M$2:$M$33,MATCH(C3,'Catalog ref'!$A$2:$A$33,0)) -> 1800
A4: A1 | B4: 2 | C4: EX-CRAWL-20T | D4: =INDEX('Catalog ref'!$C$2:$C$33,MATCH(C4,'Catalog ref'!$A$2:$A$33,0)) -> 20-25 t (~48,500-62,800 lb) | E4: 1 | F4: Y | G4: main | I4: EW-CUTLOAD | J4: =IFERROR(INDEX('Catalog production'!$D$2:$D$15,MATCH(C4&"|"&I4,'Catalog production'!$A$2:$A$15,0))*1,"") -> 163.344 | K4: =IFERROR(INDEX('Catalog production'!$E$2:$E$15,MATCH(C4&"|"&I4,'Catalog production'!$A$2:$A$15,0))&"","") -> BCY/hr | L4: =IF(N(J4)=0,"",E4*J4*Settings!$B$2*IF(K4="LCY/hr",1/Settings!$B$3,1)) -> 1633.44 | M4: =INDEX('Catalog ref'!$D$2:$D$33,MATCH(C4,'Catalog ref'!$A$2:$A$33,0)) -> 1040 | N4: =INDEX('Catalog ref'!$K$2:$K$33,MATCH(C4,'Catalog ref'!$A$2:$A$33,0)) -> 2.78 | O4: =INDEX('Catalog ref'!$M$2:$M$33,MATCH(C4,'Catalog ref'!$A$2:$A$33,0)) -> 550
A5: A1 | B5: 2 | C5: ADT-25T | D5: =INDEX('Catalog ref'!$C$2:$C$33,MATCH(C5,'Catalog ref'!$A$2:$A$33,0)) -> 26.5 t payload | E5: 2 | M5: =INDEX('Catalog ref'!$D$2:$D$33,MATCH(C5,'Catalog ref'!$A$2:$A$33,0)) -> 1882 | N5: =INDEX('Catalog ref'!$K$2:$K$33,MATCH(C5,'Catalog ref'!$A$2:$A$33,0)) -> 4.56 | O5: =INDEX('Catalog ref'!$M$2:$M$33,MATCH(C5,'Catalog ref'!$A$2:$A$33,0)) -> 1800
A6: A1 | B6: 3 | C6: EX-CRAWL-20T | D6: =INDEX('Catalog ref'!$C$2:$C$33,MATCH(C6,'Catalog ref'!$A$2:$A$33,0)) -> 20-25 t (~48,500-62,800 lb) | E6: 1 | F6: Y | G6: main | I6: EW-CUTLOAD | J6: =IFERROR(INDEX('Catalog production'!$D$2:$D$15,MATCH(C6&"|"&I6,'Catalog production'!$A$2:$A$15,0))*1,"") -> 163.344 | K6: =IFERROR(INDEX('Catalog production'!$E$2:$E$15,MATCH(C6&"|"&I6,'Catalog production'!$A$2:$A$15,0))&"","") -> BCY/hr | L6: =IF(N(J6)=0,"",E6*J6*Settings!$B$2*IF(K6="LCY/hr",1/Settings!$B$3,1)) -> 1633.44 | M6: =INDEX('Catalog ref'!$D$2:$D$33,MATCH(C6,'Catalog ref'!$A$2:$A$33,0)) -> 1040 | N6: =INDEX('Catalog ref'!$K$2:$K$33,MATCH(C6,'Catalog ref'!$A$2:$A$33,0)) -> 2.78 | O6: =INDEX('Catalog ref'!$M$2:$M$33,MATCH(C6,'Catalog ref'!$A$2:$A$33,0)) -> 550
A7: A1 | B7: 3 | C7: ADT-30T | D7: =INDEX('Catalog ref'!$C$2:$C$33,MATCH(C7,'Catalog ref'!$A$2:$A$33,0)) -> 30 t payload | E7: 2 | M7: =INDEX('Catalog ref'!$D$2:$D$33,MATCH(C7,'Catalog ref'!$A$2:$A$33,0)) -> 2126 | N7: =INDEX('Catalog ref'!$K$2:$K$33,MATCH(C7,'Catalog ref'!$A$2:$A$33,0)) -> 4.38 | O7: =INDEX('Catalog ref'!$M$2:$M$33,MATCH(C7,'Catalog ref'!$A$2:$A$33,0)) -> 1800
A8: A1 | B8: 4 | C8: EX-CRAWL-30T | D8: =INDEX('Catalog ref'!$C$2:$C$33,MATCH(C8,'Catalog ref'!$A$2:$A$33,0)) -> 30-36 t (~68,000-81,000 lb) | E8: 1 | F8: Y | G8: main | I8: EW-CUTLOAD | J8: =IFERROR(INDEX('Catalog production'!$D$2:$D$15,MATCH(C8&"|"&I8,'Catalog production'!$A$2:$A$15,0))*1,"") -> 310.752 | K8: =IFERROR(INDEX('Catalog production'!$E$2:$E$15,MATCH(C8&"|"&I8,'Catalog production'!$A$2:$A$15,0))&"","") -> BCY/hr | L8: =IF(N(J8)=0,"",E8*J8*Settings!$B$2*IF(K8="LCY/hr",1/Settings!$B$3,1)) -> 3107.52 | M8: =INDEX('Catalog ref'!$D$2:$D$33,MATCH(C8,'Catalog ref'!$A$2:$A$33,0)) -> 1424 | N8: =INDEX('Catalog ref'!$K$2:$K$33,MATCH(C8,'Catalog ref'!$A$2:$A$33,0)) -> 4.5 | O8: =INDEX('Catalog ref'!$M$2:$M$33,MATCH(C8,'Catalog ref'!$A$2:$A$33,0)) -> 1800
A9: A1 | B9: 4 | C9: ADT-30T | D9: =INDEX('Catalog ref'!$C$2:$C$33,MATCH(C9,'Catalog ref'!$A$2:$A$33,0)) -> 30 t payload | E9: 2 | M9: =INDEX('Catalog ref'!$D$2:$D$33,MATCH(C9,'Catalog ref'!$A$2:$A$33,0)) -> 2126 | N9: =INDEX('Catalog ref'!$K$2:$K$33,MATCH(C9,'Catalog ref'!$A$2:$A$33,0)) -> 4.38 | O9: =INDEX('Catalog ref'!$M$2:$M$33,MATCH(C9,'Catalog ref'!$A$2:$A$33,0)) -> 1800
A10: A1 | B10: 5 | C10: EX-CRAWL-30T | D10: =INDEX('Catalog ref'!$C$2:$C$33,MATCH(C10,'Catalog ref'!$A$2:$A$33,0)) -> 30-36 t (~68,000-81,000 lb) | E10: 1 | F10: Y | G10: main | I10: EW-CUTLOAD | J10: =IFERROR(INDEX('Catalog production'!$D$2:$D$15,MATCH(C10&"|"&I10,'Catalog production'!$A$2:$A$15,0))*1,"") -> 310.752 | K10: =IFERROR(INDEX('Catalog production'!$E$2:$E$15,MATCH(C10&"|"&I10,'Catalog production'!$A$2:$A$15,0))&"","") -> BCY/hr | L10: =IF(N(J10)=0,"",E10*J10*Settings!$B$2*IF(K10="LCY/hr",1/Settings!$B$3,1)) -> 3107.52 | M10: =INDEX('Catalog ref'!$D$2:$D$33,MATCH(C10,'Catalog ref'!$A$2:$A$33,0)) -> 1424 | N10: =INDEX('Catalog ref'!$K$2:$K$33,MATCH(C10,'Catalog ref'!$A$2:$A$33,0)) -> 4.5 | O10: =INDEX('Catalog ref'!$M$2:$M$33,MATCH(C10,'Catalog ref'!$A$2:$A$33,0)) -> 1800
A11: A1 | B11: 5 | C11: ADT-30T | D11: =INDEX('Catalog ref'!$C$2:$C$33,MATCH(C11,'Catalog ref'!$A$2:$A$33,0)) -> 30 t payload | E11: 3 | M11: =INDEX('Catalog ref'!$D$2:$D$33,MATCH(C11,'Catalog ref'!$A$2:$A$33,0)) -> 2126 | N11: =INDEX('Catalog ref'!$K$2:$K$33,MATCH(C11,'Catalog ref'!$A$2:$A$33,0)) -> 4.38 | O11: =INDEX('Catalog ref'!$M$2:$M$33,MATCH(C11,'Catalog ref'!$A$2:$A$33,0)) -> 1800
A12: A1 | B12: 6 | C12: EX-CRAWL-50T | D12: =INDEX('Catalog ref'!$C$2:$C$33,MATCH(C12,'Catalog ref'!$A$2:$A$33,0)) -> 45-55 t (~105,000-108,000 lb) | E12: 1 | F12: Y | G12: main | I12: EW-CUTLOAD | J12: =IFERROR(INDEX('Catalog production'!$D$2:$D$15,MATCH(C12&"|"&I12,'Catalog production'!$A$2:$A$15,0))*1,"") -> 510.90816 | K12: =IFERROR(INDEX('Catalog production'!$E$2:$E$15,MATCH(C12&"|"&I12,'Catalog production'!$A$2:$A$15,0))&"","") -> BCY/hr | L12: =IF(N(J12)=0,"",E12*J12*Settings!$B$2*IF(K12="LCY/hr",1/Settings!$B$3,1)) -> 5109.0816 | M12: =INDEX('Catalog ref'!$D$2:$D$33,MATCH(C12,'Catalog ref'!$A$2:$A$33,0)) -> 2250 | N12: =INDEX('Catalog ref'!$K$2:$K$33,MATCH(C12,'Catalog ref'!$A$2:$A$33,0)) -> 8.02 | O12: =INDEX('Catalog ref'!$M$2:$M$33,MATCH(C12,'Catalog ref'!$A$2:$A$33,0)) -> 1913
A13: A1 | B13: 6 | C13: ADT-30T | D13: =INDEX('Catalog ref'!$C$2:$C$33,MATCH(C13,'Catalog ref'!$A$2:$A$33,0)) -> 30 t payload | E13: 3 | M13: =INDEX('Catalog ref'!$D$2:$D$33,MATCH(C13,'Catalog ref'!$A$2:$A$33,0)) -> 2126 | N13: =INDEX('Catalog ref'!$K$2:$K$33,MATCH(C13,'Catalog ref'!$A$2:$A$33,0)) -> 4.38 | O13: =INDEX('Catalog ref'!$M$2:$M$33,MATCH(C13,'Catalog ref'!$A$2:$A$33,0)) -> 1800
A14: A1 | B14: 7 | C14: EX-CRAWL-50T | D14: =INDEX('Catalog ref'!$C$2:$C$33,MATCH(C14,'Catalog ref'!$A$2:$A$33,0)) -> 45-55 t (~105,000-108,000 lb) | E14: 1 | F14: Y | G14: main | I14: EW-CUTLOAD | J14: =IFERROR(INDEX('Catalog production'!$D$2:$D$15,MATCH(C14&"|"&I14,'Catalog production'!$A$2:$A$15,0))*1,"") -> 510.90816 | K14: =IFERROR(INDEX('Catalog production'!$E$2:$E$15,MATCH(C14&"|"&I14,'Catalog production'!$A$2:$A$15,0))&"","") -> BCY/hr | L14: =IF(N(J14)=0,"",E14*J14*Settings!$B$2*IF(K14="LCY/hr",1/Settings!$B$3,1)) -> 5109.0816 | M14: =INDEX('Catalog ref'!$D$2:$D$33,MATCH(C14,'Catalog ref'!$A$2:$A$33,0)) -> 2250 | N14: =INDEX('Catalog ref'!$K$2:$K$33,MATCH(C14,'Catalog ref'!$A$2:$A$33,0)) -> 8.02 | O14: =INDEX('Catalog ref'!$M$2:$M$33,MATCH(C14,'Catalog ref'!$A$2:$A$33,0)) -> 1913
A15: A1 | B15: 7 | C15: ADT-30T | D15: =INDEX('Catalog ref'!$C$2:$C$33,MATCH(C15,'Catalog ref'!$A$2:$A$33,0)) -> 30 t payload | E15: 4 | M15: =INDEX('Catalog ref'!$D$2:$D$33,MATCH(C15,'Catalog ref'!$A$2:$A$33,0)) -> 2126 | N15: =INDEX('Catalog ref'!$K$2:$K$33,MATCH(C15,'Catalog ref'!$A$2:$A$33,0)) -> 4.38 | O15: =INDEX('Catalog ref'!$M$2:$M$33,MATCH(C15,'Catalog ref'!$A$2:$A$33,0)) -> 1800
A16: A1 | B16: 8 | C16: EX-CRAWL-50T | D16: =INDEX('Catalog ref'!$C$2:$C$33,MATCH(C16,'Catalog ref'!$A$2:$A$33,0)) -> 45-55 t (~105,000-108,000 lb) | E16: 2 | F16: Y | G16: main | I16: EW-CUTLOAD | J16: =IFERROR(INDEX('Catalog production'!$D$2:$D$15,MATCH(C16&"|"&I16,'Catalog production'!$A$2:$A$15,0))*1,"") -> 510.90816 | K16: =IFERROR(INDEX('Catalog production'!$E$2:$E$15,MATCH(C16&"|"&I16,'Catalog production'!$A$2:$A$15,0))&"","") -> BCY/hr | L16: =IF(N(J16)=0,"",E16*J16*Settings!$B$2*IF(K16="LCY/hr",1/Settings!$B$3,1)) -> 10218.163 | M16: =INDEX('Catalog ref'!$D$2:$D$33,MATCH(C16,'Catalog ref'!$A$2:$A$33,0)) -> 2250 | N16: =INDEX('Catalog ref'!$K$2:$K$33,MATCH(C16,'Catalog ref'!$A$2:$A$33,0)) -> 8.02 | O16: =INDEX('Catalog ref'!$M$2:$M$33,MATCH(C16,'Catalog ref'!$A$2:$A$33,0)) -> 1913
A17: A1 | B17: 8 | C17: ADT-30T | D17: =INDEX('Catalog ref'!$C$2:$C$33,MATCH(C17,'Catalog ref'!$A$2:$A$33,0)) -> 30 t payload | E17: 6 | M17: =INDEX('Catalog ref'!$D$2:$D$33,MATCH(C17,'Catalog ref'!$A$2:$A$33,0)) -> 2126 | N17: =INDEX('Catalog ref'!$K$2:$K$33,MATCH(C17,'Catalog ref'!$A$2:$A$33,0)) -> 4.38 | O17: =INDEX('Catalog ref'!$M$2:$M$33,MATCH(C17,'Catalog ref'!$A$2:$A$33,0)) -> 1800
A18: A1 | B18: 9 | C18: EX-CRAWL-70T | D18: =INDEX('Catalog ref'!$C$2:$C$33,MATCH(C18,'Catalog ref'!$A$2:$A$33,0)) -> 65-75 t (~145,000-163,000 lb) | E18: 2 | F18: Y | G18: main | I18: EW-CUTLOAD | J18: =IFERROR(INDEX('Catalog production'!$D$2:$D$15,MATCH(C18&"|"&I18,'Catalog production'!$A$2:$A$15,0))*1,"") -> 796.8 | K18: =IFERROR(INDEX('Catalog production'!$E$2:$E$15,MATCH(C18&"|"&I18,'Catalog production'!$A$2:$A$15,0))&"","") -> BCY/hr | L18: =IF(N(J18)=0,"",E18*J18*Settings!$B$2*IF(K18="LCY/hr",1/Settings!$B$3,1)) -> 15936 | M18: =INDEX('Catalog ref'!$D$2:$D$33,MATCH(C18,'Catalog ref'!$A$2:$A$33,0)) -> 3950 | N18: =INDEX('Catalog ref'!$K$2:$K$33,MATCH(C18,'Catalog ref'!$A$2:$A$33,0)) -> 9.95 | O18: =INDEX('Catalog ref'!$M$2:$M$33,MATCH(C18,'Catalog ref'!$A$2:$A$33,0)) -> 1913
A19: A1 | B19: 9 | C19: ADT-30T | D19: =INDEX('Catalog ref'!$C$2:$C$33,MATCH(C19,'Catalog ref'!$A$2:$A$33,0)) -> 30 t payload | E19: 9 | M19: =INDEX('Catalog ref'!$D$2:$D$33,MATCH(C19,'Catalog ref'!$A$2:$A$33,0)) -> 2126 | N19: =INDEX('Catalog ref'!$K$2:$K$33,MATCH(C19,'Catalog ref'!$A$2:$A$33,0)) -> 4.38 | O19: =INDEX('Catalog ref'!$M$2:$M$33,MATCH(C19,'Catalog ref'!$A$2:$A$33,0)) -> 1800
